[2022-03-30 14:09:08,516][urllib3.connectionpool][WARNING] - Retrying (Retry(total=4, connect=4, read=5, redirect=None, status=None)) after connection broken by 'NewConnectionError('<urllib3.connection.HTTPConnection object at 0x7f217420fe80>: Failed to establish a new connection: [Errno 111] Connection refused')': /
[2022-03-30 14:09:12,519][urllib3.connectionpool][WARNING] - Retrying (Retry(total=3, connect=3, read=5, redirect=None, status=None)) after connection broken by 'NewConnectionError('<urllib3.connection.HTTPConnection object at 0x7f217420fd90>: Failed to establish a new connection: [Errno 111] Connection refused')': /
[2022-03-30 14:09:34,004][root][ERROR] - Error
Traceback (most recent call last):
  File "/data/vision/torralba/frames/data_acquisition/SyntheticStories/agent_preferences/tshu/agent_preferences/analysis/helping_states.py", line 821, in main
    actions, curr_info = arena.get_actions(
  File "/data/vision/torralba/frames/data_acquisition/SyntheticStories/agent_preferences/tshu/agent_preferences/algos/arena_mp2.py", line 127, in get_actions
    dict_actions[it], dict_info[it] = agent.get_action(
  File "/data/vision/torralba/frames/data_acquisition/SyntheticStories/agent_preferences/tshu/agent_preferences/agents/MCTS_agent_particle_v2_instance.py", line 1179, in get_action
    plan, root_node, subgoals = get_plan(
  File "/data/vision/torralba/frames/data_acquisition/SyntheticStories/agent_preferences/tshu/agent_preferences/agents/MCTS_agent_particle_v2_instance.py", line 726, in get_plan
    info_item.re_raise()
  File "/data/vision/torralba/frames/data_acquisition/SyntheticStories/agent_preferences/tshu/agent_preferences/utils/utils_exception.py", line 24, in re_raise
    raise self.ee.with_traceback(self.tb)
  File "/data/vision/torralba/frames/data_acquisition/SyntheticStories/agent_preferences/tshu/agent_preferences/agents/MCTS_agent_particle_v2_instance.py", line 627, in mp_run_mcts
    res = new_mcts.run(
  File "/data/vision/torralba/frames/data_acquisition/SyntheticStories/agent_preferences/tshu/agent_preferences/MCTS/MCTS_particles_v2_instance.py", line 234, in run
    next_node, next_state, cost, reward = self.select_child(
  File "/data/vision/torralba/frames/data_acquisition/SyntheticStories/agent_preferences/tshu/agent_preferences/MCTS/MCTS_particles_v2_instance.py", line 793, in select_child
    success, next_vh_state, next_state_dict, cost, reward = self.transition(
  File "/data/vision/torralba/frames/data_acquisition/SyntheticStories/agent_preferences/tshu/agent_preferences/MCTS/MCTS_particles_v2_instance.py", line 685, in transition
    success, next_vh_state = self.env.transition(curr_vh_state, action)
  File "/data/vision/torralba/frames/data_acquisition/SyntheticStories/agent_preferences/tshu/agent_preferences/envs/graph_env.py", line 532, in transition
    next_vh_state = init_from_state(
  File "/data/vision/torralba/frames/data_acquisition/SyntheticStories/agent_preferences/tshu/agent_preferences/envs/graph_env.py", line 28, in init_from_state
    env_state._graph,
AttributeError: 'NoneType' object has no attribute '_graph'
[2022-03-30 14:09:34,114][urllib3.connectionpool][WARNING] - Retrying (Retry(total=4, connect=4, read=5, redirect=None, status=None)) after connection broken by 'NewConnectionError('<urllib3.connection.HTTPConnection object at 0x7f21bede5310>: Failed to establish a new connection: [Errno 111] Connection refused')': /
[2022-03-30 14:09:38,115][urllib3.connectionpool][WARNING] - Retrying (Retry(total=3, connect=3, read=5, redirect=None, status=None)) after connection broken by 'NewConnectionError('<urllib3.connection.HTTPConnection object at 0x7f21be5129a0>: Failed to establish a new connection: [Errno 111] Connection refused')': /
[2022-03-30 14:10:38,688][root][ERROR] - Error
Traceback (most recent call last):
  File "/data/vision/torralba/frames/data_acquisition/SyntheticStories/agent_preferences/tshu/agent_preferences/analysis/helping_states.py", line 821, in main
    actions, curr_info = arena.get_actions(
  File "/data/vision/torralba/frames/data_acquisition/SyntheticStories/agent_preferences/tshu/agent_preferences/algos/arena_mp2.py", line 127, in get_actions
    dict_actions[it], dict_info[it] = agent.get_action(
  File "/data/vision/torralba/frames/data_acquisition/SyntheticStories/agent_preferences/tshu/agent_preferences/agents/MCTS_agent_particle_v2_instance.py", line 1179, in get_action
    plan, root_node, subgoals = get_plan(
  File "/data/vision/torralba/frames/data_acquisition/SyntheticStories/agent_preferences/tshu/agent_preferences/agents/MCTS_agent_particle_v2_instance.py", line 721, in get_plan
    info = [mp_run(rn) for rn in root_nodes]
  File "/data/vision/torralba/frames/data_acquisition/SyntheticStories/agent_preferences/tshu/agent_preferences/utils/utils_exception.py", line 24, in re_raise
    raise self.ee.with_traceback(self.tb)
  File "/data/vision/torralba/frames/data_acquisition/SyntheticStories/agent_preferences/tshu/agent_preferences/agents/MCTS_agent_particle_v2_instance.py", line 627, in mp_run_mcts
    res = new_mcts.run(
  File "/data/vision/torralba/frames/data_acquisition/SyntheticStories/agent_preferences/tshu/agent_preferences/MCTS/MCTS_particles_v2_instance.py", line 234, in run
    next_node, next_state, cost, reward = self.select_child(
  File "/data/vision/torralba/frames/data_acquisition/SyntheticStories/agent_preferences/tshu/agent_preferences/MCTS/MCTS_particles_v2_instance.py", line 793, in select_child
    success, next_vh_state, next_state_dict, cost, reward = self.transition(
  File "/data/vision/torralba/frames/data_acquisition/SyntheticStories/agent_preferences/tshu/agent_preferences/MCTS/MCTS_particles_v2_instance.py", line 685, in transition
    success, next_vh_state = self.env.transition(curr_vh_state, action)
  File "/data/vision/torralba/frames/data_acquisition/SyntheticStories/agent_preferences/tshu/agent_preferences/envs/graph_env.py", line 532, in transition
    next_vh_state = init_from_state(
  File "/data/vision/torralba/frames/data_acquisition/SyntheticStories/agent_preferences/tshu/agent_preferences/envs/graph_env.py", line 532, in transition
    next_vh_state = init_from_state(
  File "/data/vision/torralba/frames/tools/anaconda3/envs/online_wah/lib/python3.9/bdb.py", line 88, in trace_dispatch
    return self.dispatch_line(frame)
  File "/data/vision/torralba/frames/tools/anaconda3/envs/online_wah/lib/python3.9/bdb.py", line 113, in dispatch_line
    if self.quitting: raise BdbQuit
bdb.BdbQuit
[2022-03-30 14:10:52,769][urllib3.connectionpool][WARNING] - Retrying (Retry(total=4, connect=4, read=5, redirect=None, status=None)) after connection broken by 'NewConnectionError('<urllib3.connection.HTTPConnection object at 0x7faddaa307c0>: Failed to establish a new connection: [Errno 111] Connection refused')': /
[2022-03-30 14:10:56,771][urllib3.connectionpool][WARNING] - Retrying (Retry(total=3, connect=3, read=5, redirect=None, status=None)) after connection broken by 'NewConnectionError('<urllib3.connection.HTTPConnection object at 0x7fadda9ca1f0>: Failed to establish a new connection: [Errno 111] Connection refused')': /
[2022-03-30 14:34:10,484][root][ERROR] - Error
Traceback (most recent call last):
  File "/data/vision/torralba/frames/data_acquisition/SyntheticStories/agent_preferences/tshu/agent_preferences/analysis/helping_states.py", line 821, in main
    actions, curr_info = arena.get_actions(
  File "/data/vision/torralba/frames/data_acquisition/SyntheticStories/agent_preferences/tshu/agent_preferences/algos/arena_mp2.py", line 127, in get_actions
    dict_actions[it], dict_info[it] = agent.get_action(
  File "/data/vision/torralba/frames/data_acquisition/SyntheticStories/agent_preferences/tshu/agent_preferences/agents/MCTS_agent_particle_v2_instance.py", line 1179, in get_action
    plan, root_node, subgoals = get_plan(
  File "/data/vision/torralba/frames/data_acquisition/SyntheticStories/agent_preferences/tshu/agent_preferences/agents/MCTS_agent_particle_v2_instance.py", line 721, in get_plan
    info = [mp_run(rn) for rn in root_nodes]
  File "/data/vision/torralba/frames/data_acquisition/SyntheticStories/agent_preferences/tshu/agent_preferences/utils/utils_exception.py", line 24, in re_raise
    raise self.ee.with_traceback(self.tb)
  File "/data/vision/torralba/frames/data_acquisition/SyntheticStories/agent_preferences/tshu/agent_preferences/agents/MCTS_agent_particle_v2_instance.py", line 627, in mp_run_mcts
    res = new_mcts.run(
  File "/data/vision/torralba/frames/data_acquisition/SyntheticStories/agent_preferences/tshu/agent_preferences/MCTS/MCTS_particles_v2_instance.py", line 234, in run
    next_node, next_state, cost, reward = self.select_child(
  File "/data/vision/torralba/frames/data_acquisition/SyntheticStories/agent_preferences/tshu/agent_preferences/MCTS/MCTS_particles_v2_instance.py", line 793, in select_child
    success, next_vh_state, next_state_dict, cost, reward = self.transition(
  File "/data/vision/torralba/frames/data_acquisition/SyntheticStories/agent_preferences/tshu/agent_preferences/MCTS/MCTS_particles_v2_instance.py", line 685, in transition
    success, next_vh_state = self.env.transition(curr_vh_state, action)
  File "/data/vision/torralba/frames/data_acquisition/SyntheticStories/agent_preferences/tshu/agent_preferences/envs/graph_env.py", line 532, in transition
    next_vh_state = init_from_state(
  File "/data/vision/torralba/frames/data_acquisition/SyntheticStories/agent_preferences/tshu/agent_preferences/envs/graph_env.py", line 532, in transition
    next_vh_state = init_from_state(
  File "/data/vision/torralba/frames/tools/anaconda3/envs/online_wah/lib/python3.9/bdb.py", line 88, in trace_dispatch
    return self.dispatch_line(frame)
  File "/data/vision/torralba/frames/tools/anaconda3/envs/online_wah/lib/python3.9/bdb.py", line 113, in dispatch_line
    if self.quitting: raise BdbQuit
bdb.BdbQuit
[2022-03-30 14:34:10,619][urllib3.connectionpool][WARNING] - Retrying (Retry(total=4, connect=4, read=5, redirect=None, status=None)) after connection broken by 'NewConnectionError('<urllib3.connection.HTTPConnection object at 0x7fae2361edc0>: Failed to establish a new connection: [Errno 111] Connection refused')': /
[2022-03-30 14:34:25,017][urllib3.connectionpool][WARNING] - Retrying (Retry(total=4, connect=4, read=5, redirect=None, status=None)) after connection broken by 'NewConnectionError('<urllib3.connection.HTTPConnection object at 0x7f65561f4ee0>: Failed to establish a new connection: [Errno 111] Connection refused')': /
[2022-03-30 14:34:29,019][urllib3.connectionpool][WARNING] - Retrying (Retry(total=3, connect=3, read=5, redirect=None, status=None)) after connection broken by 'NewConnectionError('<urllib3.connection.HTTPConnection object at 0x7f65562ab3d0>: Failed to establish a new connection: [Errno 111] Connection refused')': /
[2022-03-30 16:13:55,488][urllib3.connectionpool][WARNING] - Retrying (Retry(total=4, connect=4, read=5, redirect=None, status=None)) after connection broken by 'NewConnectionError('<urllib3.connection.HTTPConnection object at 0x7f3c915c67c0>: Failed to establish a new connection: [Errno 111] Connection refused')': /
[2022-03-30 16:13:59,491][urllib3.connectionpool][WARNING] - Retrying (Retry(total=3, connect=3, read=5, redirect=None, status=None)) after connection broken by 'NewConnectionError('<urllib3.connection.HTTPConnection object at 0x7f3c9150c280>: Failed to establish a new connection: [Errno 111] Connection refused')': /
[2022-03-30 16:14:23,593][root][ERROR] - Error
Traceback (most recent call last):
  File "/data/vision/torralba/frames/data_acquisition/SyntheticStories/agent_preferences/tshu/agent_preferences/analysis/helping_states.py", line 1409, in main
    print(get_class_from_state(gt_graph))
NameError: name 'gt_graph' is not defined
[2022-03-30 16:14:23,717][urllib3.connectionpool][WARNING] - Retrying (Retry(total=4, connect=4, read=5, redirect=None, status=None)) after connection broken by 'NewConnectionError('<urllib3.connection.HTTPConnection object at 0x7f3ce0e06ca0>: Failed to establish a new connection: [Errno 111] Connection refused')': /
[2022-03-30 16:14:27,722][urllib3.connectionpool][WARNING] - Retrying (Retry(total=3, connect=3, read=5, redirect=None, status=None)) after connection broken by 'NewConnectionError('<urllib3.connection.HTTPConnection object at 0x7f3ce0e06df0>: Failed to establish a new connection: [Errno 111] Connection refused')': /
[2022-03-30 16:15:21,626][root][ERROR] - Error
Traceback (most recent call last):
  File "/data/vision/torralba/frames/data_acquisition/SyntheticStories/agent_preferences/tshu/agent_preferences/analysis/helping_states.py", line 1409, in main
    print(get_class_from_state(gt_graph))
NameError: name 'gt_graph' is not defined
[2022-03-30 16:17:15,224][urllib3.connectionpool][WARNING] - Retrying (Retry(total=4, connect=4, read=5, redirect=None, status=None)) after connection broken by 'NewConnectionError('<urllib3.connection.HTTPConnection object at 0x7f4fa9e521c0>: Failed to establish a new connection: [Errno 111] Connection refused')': /
[2022-03-30 16:17:19,227][urllib3.connectionpool][WARNING] - Retrying (Retry(total=3, connect=3, read=5, redirect=None, status=None)) after connection broken by 'NewConnectionError('<urllib3.connection.HTTPConnection object at 0x7f4fa9e52850>: Failed to establish a new connection: [Errno 111] Connection refused')': /
[2022-03-30 16:17:46,077][root][ERROR] - Error
Traceback (most recent call last):
  File "/data/vision/torralba/frames/data_acquisition/SyntheticStories/agent_preferences/tshu/agent_preferences/analysis/helping_states.py", line 1409, in main
    print(get_class_from_state(gt_graph))
NameError: name 'gt_graph' is not defined
[2022-03-30 16:17:46,222][urllib3.connectionpool][WARNING] - Retrying (Retry(total=4, connect=4, read=5, redirect=None, status=None)) after connection broken by 'NewConnectionError('<urllib3.connection.HTTPConnection object at 0x7f4ff98a9880>: Failed to establish a new connection: [Errno 111] Connection refused')': /
[2022-03-30 16:17:50,227][urllib3.connectionpool][WARNING] - Retrying (Retry(total=3, connect=3, read=5, redirect=None, status=None)) after connection broken by 'NewConnectionError('<urllib3.connection.HTTPConnection object at 0x7f4ff98a9d30>: Failed to establish a new connection: [Errno 111] Connection refused')': /
[2022-03-30 16:17:58,569][urllib3.connectionpool][WARNING] - Retrying (Retry(total=4, connect=4, read=5, redirect=None, status=None)) after connection broken by 'NewConnectionError('<urllib3.connection.HTTPConnection object at 0x7f4f8066b400>: Failed to establish a new connection: [Errno 111] Connection refused')': /
[2022-03-30 16:18:19,760][urllib3.connectionpool][WARNING] - Retrying (Retry(total=4, connect=4, read=5, redirect=None, status=None)) after connection broken by 'NewConnectionError('<urllib3.connection.HTTPConnection object at 0x7fb6bec2f0a0>: Failed to establish a new connection: [Errno 111] Connection refused')': /
[2022-03-30 16:18:23,766][urllib3.connectionpool][WARNING] - Retrying (Retry(total=3, connect=3, read=5, redirect=None, status=None)) after connection broken by 'NewConnectionError('<urllib3.connection.HTTPConnection object at 0x7fb6bec2f730>: Failed to establish a new connection: [Errno 111] Connection refused')': /
[2022-03-30 16:18:50,450][root][ERROR] - Error
Traceback (most recent call last):
  File "/data/vision/torralba/frames/data_acquisition/SyntheticStories/agent_preferences/tshu/agent_preferences/analysis/helping_states.py", line 1409, in main
    print(get_class_from_state(init_gr))
  File "/data/vision/torralba/frames/data_acquisition/SyntheticStories/agent_preferences/tshu/agent_preferences/analysis/helping_states.py", line 120, in get_class_from_state
    nodes = pred["nodes"]
NameError: name 'pred' is not defined
[2022-03-30 16:18:50,585][urllib3.connectionpool][WARNING] - Retrying (Retry(total=4, connect=4, read=5, redirect=None, status=None)) after connection broken by 'NewConnectionError('<urllib3.connection.HTTPConnection object at 0x7fb6fc4ed370>: Failed to establish a new connection: [Errno 111] Connection refused')': /
[2022-03-30 16:18:54,589][urllib3.connectionpool][WARNING] - Retrying (Retry(total=3, connect=3, read=5, redirect=None, status=None)) after connection broken by 'NewConnectionError('<urllib3.connection.HTTPConnection object at 0x7fb6fc4ed340>: Failed to establish a new connection: [Errno 111] Connection refused')': /
[2022-03-30 16:20:14,295][urllib3.connectionpool][WARNING] - Retrying (Retry(total=4, connect=4, read=5, redirect=None, status=None)) after connection broken by 'NewConnectionError('<urllib3.connection.HTTPConnection object at 0x7f0c5091df40>: Failed to establish a new connection: [Errno 111] Connection refused')': /
[2022-03-30 16:20:18,300][urllib3.connectionpool][WARNING] - Retrying (Retry(total=3, connect=3, read=5, redirect=None, status=None)) after connection broken by 'NewConnectionError('<urllib3.connection.HTTPConnection object at 0x7f0c50736730>: Failed to establish a new connection: [Errno 111] Connection refused')': /
[2022-03-30 16:20:35,374][root][ERROR] - Error
Traceback (most recent call last):
  File "/data/vision/torralba/frames/data_acquisition/SyntheticStories/agent_preferences/tshu/agent_preferences/analysis/helping_states.py", line 1289, in main
    print(get_class_from_state(init_gr))
  File "/data/vision/torralba/frames/data_acquisition/SyntheticStories/agent_preferences/tshu/agent_preferences/analysis/helping_states.py", line 132, in get_class_from_state
    edge_name = edges[edge_id]["edge_class"].lower()
KeyError: 'edge_class'
[2022-03-30 16:20:35,498][urllib3.connectionpool][WARNING] - Retrying (Retry(total=4, connect=4, read=5, redirect=None, status=None)) after connection broken by 'NewConnectionError('<urllib3.connection.HTTPConnection object at 0x7f0c8df7fb80>: Failed to establish a new connection: [Errno 111] Connection refused')': /
[2022-03-30 16:20:39,503][urllib3.connectionpool][WARNING] - Retrying (Retry(total=3, connect=3, read=5, redirect=None, status=None)) after connection broken by 'NewConnectionError('<urllib3.connection.HTTPConnection object at 0x7f0c8df38220>: Failed to establish a new connection: [Errno 111] Connection refused')': /
[2022-03-30 16:20:53,410][root][ERROR] - Error
Traceback (most recent call last):
  File "/data/vision/torralba/frames/data_acquisition/SyntheticStories/agent_preferences/tshu/agent_preferences/analysis/helping_states.py", line 1289, in main
    print(get_class_from_state(init_gr))
  File "/data/vision/torralba/frames/data_acquisition/SyntheticStories/agent_preferences/tshu/agent_preferences/analysis/helping_states.py", line 132, in get_class_from_state
    edge_name = edges[edge_id]["edge_class"].lower()
KeyError: 'edge_class'
[2022-03-30 16:23:31,383][urllib3.connectionpool][WARNING] - Retrying (Retry(total=4, connect=4, read=5, redirect=None, status=None)) after connection broken by 'NewConnectionError('<urllib3.connection.HTTPConnection object at 0x7f8a43684040>: Failed to establish a new connection: [Errno 111] Connection refused')': /
[2022-03-30 16:23:35,388][urllib3.connectionpool][WARNING] - Retrying (Retry(total=3, connect=3, read=5, redirect=None, status=None)) after connection broken by 'NewConnectionError('<urllib3.connection.HTTPConnection object at 0x7f8a436846d0>: Failed to establish a new connection: [Errno 111] Connection refused')': /
[2022-03-30 16:23:52,899][root][ERROR] - Error
Traceback (most recent call last):
  File "/data/vision/torralba/frames/data_acquisition/SyntheticStories/agent_preferences/tshu/agent_preferences/analysis/helping_states.py", line 1289, in main
    print(get_class_from_state(init_gr))
  File "/data/vision/torralba/frames/data_acquisition/SyntheticStories/agent_preferences/tshu/agent_preferences/analysis/helping_states.py", line 154, in get_class_from_state
    if edge_class not in edge_pred_class:
NameError: name 'edge_pred_class' is not defined
[2022-03-30 16:23:53,053][urllib3.connectionpool][WARNING] - Retrying (Retry(total=4, connect=4, read=5, redirect=None, status=None)) after connection broken by 'NewConnectionError('<urllib3.connection.HTTPConnection object at 0x7f8a80eb5400>: Failed to establish a new connection: [Errno 111] Connection refused')': /
[2022-03-30 16:23:57,058][urllib3.connectionpool][WARNING] - Retrying (Retry(total=3, connect=3, read=5, redirect=None, status=None)) after connection broken by 'NewConnectionError('<urllib3.connection.HTTPConnection object at 0x7f8a80eb5220>: Failed to establish a new connection: [Errno 111] Connection refused')': /
[2022-03-30 16:24:11,450][root][ERROR] - Error
Traceback (most recent call last):
  File "/data/vision/torralba/frames/data_acquisition/SyntheticStories/agent_preferences/tshu/agent_preferences/analysis/helping_states.py", line 1289, in main
    print(get_class_from_state(init_gr))
  File "/data/vision/torralba/frames/data_acquisition/SyntheticStories/agent_preferences/tshu/agent_preferences/analysis/helping_states.py", line 154, in get_class_from_state
    if edge_class not in edge_pred_class:
NameError: name 'edge_pred_class' is not defined
[2022-03-30 16:27:19,342][urllib3.connectionpool][WARNING] - Retrying (Retry(total=4, connect=4, read=5, redirect=None, status=None)) after connection broken by 'NewConnectionError('<urllib3.connection.HTTPConnection object at 0x7efd3e838730>: Failed to establish a new connection: [Errno 111] Connection refused')': /
[2022-03-30 16:27:23,347][urllib3.connectionpool][WARNING] - Retrying (Retry(total=3, connect=3, read=5, redirect=None, status=None)) after connection broken by 'NewConnectionError('<urllib3.connection.HTTPConnection object at 0x7efd3e77f4f0>: Failed to establish a new connection: [Errno 111] Connection refused')': /
[2022-03-30 16:27:40,605][root][ERROR] - Error
Traceback (most recent call last):
  File "/data/vision/torralba/frames/data_acquisition/SyntheticStories/agent_preferences/tshu/agent_preferences/analysis/helping_states.py", line 1289, in main
    print(get_class_from_state(init_gr))
  File "/data/vision/torralba/frames/data_acquisition/SyntheticStories/agent_preferences/tshu/agent_preferences/analysis/helping_states.py", line 157, in get_class_from_state
    edge_class[edge_class] += 1
TypeError: string indices must be integers
[2022-03-30 16:27:40,730][urllib3.connectionpool][WARNING] - Retrying (Retry(total=4, connect=4, read=5, redirect=None, status=None)) after connection broken by 'NewConnectionError('<urllib3.connection.HTTPConnection object at 0x7efd7dfe30a0>: Failed to establish a new connection: [Errno 111] Connection refused')': /
[2022-03-30 16:27:44,735][urllib3.connectionpool][WARNING] - Retrying (Retry(total=3, connect=3, read=5, redirect=None, status=None)) after connection broken by 'NewConnectionError('<urllib3.connection.HTTPConnection object at 0x7efd7dfe3190>: Failed to establish a new connection: [Errno 111] Connection refused')': /
[2022-03-30 16:28:27,518][urllib3.connectionpool][WARNING] - Retrying (Retry(total=4, connect=4, read=5, redirect=None, status=None)) after connection broken by 'NewConnectionError('<urllib3.connection.HTTPConnection object at 0x7f73f5b2a160>: Failed to establish a new connection: [Errno 111] Connection refused')': /
[2022-03-30 16:28:31,519][urllib3.connectionpool][WARNING] - Retrying (Retry(total=3, connect=3, read=5, redirect=None, status=None)) after connection broken by 'NewConnectionError('<urllib3.connection.HTTPConnection object at 0x7f73f5b04520>: Failed to establish a new connection: [Errno 111] Connection refused')': /
[2022-03-30 16:28:48,969][root][ERROR] - Error
Traceback (most recent call last):
  File "/data/vision/torralba/frames/data_acquisition/SyntheticStories/agent_preferences/tshu/agent_preferences/analysis/helping_states.py", line 1291, in main
    print(get_class_from_state(curr_obs))
  File "/data/vision/torralba/frames/data_acquisition/SyntheticStories/agent_preferences/tshu/agent_preferences/analysis/helping_states.py", line 118, in get_class_from_state
    id2node = {node["id"]: node["class_name"] for node in state["nodes"]}
KeyError: 'nodes'
[2022-03-30 16:28:49,141][urllib3.connectionpool][WARNING] - Retrying (Retry(total=4, connect=4, read=5, redirect=None, status=None)) after connection broken by 'NewConnectionError('<urllib3.connection.HTTPConnection object at 0x7f7433473520>: Failed to establish a new connection: [Errno 111] Connection refused')': /
[2022-03-30 16:28:53,143][urllib3.connectionpool][WARNING] - Retrying (Retry(total=3, connect=3, read=5, redirect=None, status=None)) after connection broken by 'NewConnectionError('<urllib3.connection.HTTPConnection object at 0x7f7433473040>: Failed to establish a new connection: [Errno 111] Connection refused')': /
[2022-03-30 16:29:24,015][urllib3.connectionpool][WARNING] - Retrying (Retry(total=4, connect=4, read=5, redirect=None, status=None)) after connection broken by 'NewConnectionError('<urllib3.connection.HTTPConnection object at 0x7fe003308fd0>: Failed to establish a new connection: [Errno 111] Connection refused')': /
[2022-03-30 16:29:28,019][urllib3.connectionpool][WARNING] - Retrying (Retry(total=3, connect=3, read=5, redirect=None, status=None)) after connection broken by 'NewConnectionError('<urllib3.connection.HTTPConnection object at 0x7fe003122730>: Failed to establish a new connection: [Errno 111] Connection refused')': /
[2022-03-30 16:29:46,200][root][ERROR] - Error
Traceback (most recent call last):
  File "/data/vision/torralba/frames/data_acquisition/SyntheticStories/agent_preferences/tshu/agent_preferences/analysis/helping_states.py", line 1292, in main
    print(get_class_from_state(curr_obs))
  File "/data/vision/torralba/frames/data_acquisition/SyntheticStories/agent_preferences/tshu/agent_preferences/analysis/helping_states.py", line 119, in get_class_from_state
    id2node = {node["id"]: node["class_name"] for node in state["nodes"]}
KeyError: 'nodes'
[2022-03-30 16:29:46,317][urllib3.connectionpool][WARNING] - Retrying (Retry(total=4, connect=4, read=5, redirect=None, status=None)) after connection broken by 'NewConnectionError('<urllib3.connection.HTTPConnection object at 0x7fe0441bd250>: Failed to establish a new connection: [Errno 111] Connection refused')': /
[2022-03-30 16:29:50,319][urllib3.connectionpool][WARNING] - Retrying (Retry(total=3, connect=3, read=5, redirect=None, status=None)) after connection broken by 'NewConnectionError('<urllib3.connection.HTTPConnection object at 0x7fe0441bd1c0>: Failed to establish a new connection: [Errno 111] Connection refused')': /
[2022-03-30 16:30:35,732][urllib3.connectionpool][WARNING] - Retrying (Retry(total=4, connect=4, read=5, redirect=None, status=None)) after connection broken by 'NewConnectionError('<urllib3.connection.HTTPConnection object at 0x7fd415f19910>: Failed to establish a new connection: [Errno 111] Connection refused')': /
[2022-03-30 16:30:39,737][urllib3.connectionpool][WARNING] - Retrying (Retry(total=3, connect=3, read=5, redirect=None, status=None)) after connection broken by 'NewConnectionError('<urllib3.connection.HTTPConnection object at 0x7fd415e1a610>: Failed to establish a new connection: [Errno 111] Connection refused')': /
[2022-03-30 16:39:52,206][root][ERROR] - Error
Traceback (most recent call last):
  File "/data/vision/torralba/frames/data_acquisition/SyntheticStories/agent_preferences/tshu/agent_preferences/analysis/helping_states.py", line 1295, in main
    dish = True
  File "/data/vision/torralba/frames/data_acquisition/SyntheticStories/agent_preferences/tshu/agent_preferences/analysis/helping_states.py", line 1295, in main
    dish = True
  File "/data/vision/torralba/frames/tools/anaconda3/envs/online_wah/lib/python3.9/bdb.py", line 88, in trace_dispatch
    return self.dispatch_line(frame)
  File "/data/vision/torralba/frames/tools/anaconda3/envs/online_wah/lib/python3.9/bdb.py", line 113, in dispatch_line
    if self.quitting: raise BdbQuit
bdb.BdbQuit
[2022-03-30 16:39:52,342][urllib3.connectionpool][WARNING] - Retrying (Retry(total=4, connect=4, read=5, redirect=None, status=None)) after connection broken by 'NewConnectionError('<urllib3.connection.HTTPConnection object at 0x7fd3e99556a0>: Failed to establish a new connection: [Errno 111] Connection refused')': /
[2022-03-30 16:40:05,250][urllib3.connectionpool][WARNING] - Retrying (Retry(total=4, connect=4, read=5, redirect=None, status=None)) after connection broken by 'NewConnectionError('<urllib3.connection.HTTPConnection object at 0x7f1a2d312880>: Failed to establish a new connection: [Errno 111] Connection refused')': /
[2022-03-30 16:40:09,255][urllib3.connectionpool][WARNING] - Retrying (Retry(total=3, connect=3, read=5, redirect=None, status=None)) after connection broken by 'NewConnectionError('<urllib3.connection.HTTPConnection object at 0x7f1a2d312f40>: Failed to establish a new connection: [Errno 111] Connection refused')': /
[2022-03-30 16:40:27,124][root][ERROR] - Error
Traceback (most recent call last):
  File "/data/vision/torralba/frames/data_acquisition/SyntheticStories/agent_preferences/tshu/agent_preferences/analysis/helping_states.py", line 1302, in main
    print("dist:", compute_dist_instance(init_gr, curr_obs[1], ""))
  File "/data/vision/torralba/frames/data_acquisition/SyntheticStories/agent_preferences/tshu/agent_preferences/analysis/helping_states.py", line 167, in compute_dist_instance
    dist += abs(init_edge_class[edge] - curr_edge_class[edge])
UnboundLocalError: local variable 'dist' referenced before assignment
[2022-03-30 16:40:27,237][urllib3.connectionpool][WARNING] - Retrying (Retry(total=4, connect=4, read=5, redirect=None, status=None)) after connection broken by 'NewConnectionError('<urllib3.connection.HTTPConnection object at 0x7f1a6cb81400>: Failed to establish a new connection: [Errno 111] Connection refused')': /
[2022-03-30 16:40:31,242][urllib3.connectionpool][WARNING] - Retrying (Retry(total=3, connect=3, read=5, redirect=None, status=None)) after connection broken by 'NewConnectionError('<urllib3.connection.HTTPConnection object at 0x7f1a6cb81490>: Failed to establish a new connection: [Errno 111] Connection refused')': /
[2022-03-30 16:40:44,883][root][ERROR] - Error
Traceback (most recent call last):
  File "/data/vision/torralba/frames/data_acquisition/SyntheticStories/agent_preferences/tshu/agent_preferences/analysis/helping_states.py", line 1302, in main
    print("dist:", compute_dist_instance(init_gr, curr_obs[1], ""))
  File "/data/vision/torralba/frames/data_acquisition/SyntheticStories/agent_preferences/tshu/agent_preferences/analysis/helping_states.py", line 167, in compute_dist_instance
    dist += abs(init_edge_class[edge] - curr_edge_class[edge])
UnboundLocalError: local variable 'dist' referenced before assignment
[2022-03-30 16:41:18,902][urllib3.connectionpool][WARNING] - Retrying (Retry(total=4, connect=4, read=5, redirect=None, status=None)) after connection broken by 'NewConnectionError('<urllib3.connection.HTTPConnection object at 0x7fe22ac41b20>: Failed to establish a new connection: [Errno 111] Connection refused')': /
[2022-03-30 16:41:22,907][urllib3.connectionpool][WARNING] - Retrying (Retry(total=3, connect=3, read=5, redirect=None, status=None)) after connection broken by 'NewConnectionError('<urllib3.connection.HTTPConnection object at 0x7fe22abec7f0>: Failed to establish a new connection: [Errno 111] Connection refused')': /
[2022-03-30 16:42:22,604][root][ERROR] - Error
Traceback (most recent call last):
  File "/data/vision/torralba/frames/data_acquisition/SyntheticStories/agent_preferences/tshu/agent_preferences/analysis/helping_states.py", line 1307, in main
    ipdb.set_trace()
  File "/data/vision/torralba/frames/data_acquisition/SyntheticStories/agent_preferences/tshu/agent_preferences/analysis/helping_states.py", line 1307, in main
    ipdb.set_trace()
  File "/data/vision/torralba/frames/tools/anaconda3/envs/online_wah/lib/python3.9/bdb.py", line 88, in trace_dispatch
    return self.dispatch_line(frame)
  File "/data/vision/torralba/frames/tools/anaconda3/envs/online_wah/lib/python3.9/bdb.py", line 113, in dispatch_line
    if self.quitting: raise BdbQuit
bdb.BdbQuit
[2022-03-30 16:42:22,757][urllib3.connectionpool][WARNING] - Retrying (Retry(total=4, connect=4, read=5, redirect=None, status=None)) after connection broken by 'NewConnectionError('<urllib3.connection.HTTPConnection object at 0x7fe1fe74f700>: Failed to establish a new connection: [Errno 111] Connection refused')': /
[2022-03-30 16:42:33,698][urllib3.connectionpool][WARNING] - Retrying (Retry(total=4, connect=4, read=5, redirect=None, status=None)) after connection broken by 'NewConnectionError('<urllib3.connection.HTTPConnection object at 0x7fa0c1a8ae20>: Failed to establish a new connection: [Errno 111] Connection refused')': /
[2022-03-30 16:42:37,703][urllib3.connectionpool][WARNING] - Retrying (Retry(total=3, connect=3, read=5, redirect=None, status=None)) after connection broken by 'NewConnectionError('<urllib3.connection.HTTPConnection object at 0x7fa0c1a37ac0>: Failed to establish a new connection: [Errno 111] Connection refused')': /
[2022-03-30 16:45:38,263][root][ERROR] - Error
Traceback (most recent call last):
  File "/data/vision/torralba/frames/data_acquisition/SyntheticStories/agent_preferences/tshu/agent_preferences/analysis/helping_states.py", line 1309, in main
  File "/data/vision/torralba/frames/data_acquisition/SyntheticStories/agent_preferences/tshu/agent_preferences/analysis/helping_states.py", line 1309, in main
  File "/data/vision/torralba/frames/tools/anaconda3/envs/online_wah/lib/python3.9/bdb.py", line 88, in trace_dispatch
    return self.dispatch_line(frame)
  File "/data/vision/torralba/frames/tools/anaconda3/envs/online_wah/lib/python3.9/bdb.py", line 113, in dispatch_line
    if self.quitting: raise BdbQuit
bdb.BdbQuit
[2022-03-30 16:45:38,392][urllib3.connectionpool][WARNING] - Retrying (Retry(total=4, connect=4, read=5, redirect=None, status=None)) after connection broken by 'NewConnectionError('<urllib3.connection.HTTPConnection object at 0x7fa095575550>: Failed to establish a new connection: [Errno 111] Connection refused')': /
[2022-03-30 16:45:50,581][urllib3.connectionpool][WARNING] - Retrying (Retry(total=4, connect=4, read=5, redirect=None, status=None)) after connection broken by 'NewConnectionError('<urllib3.connection.HTTPConnection object at 0x7f4b3e4f0fa0>: Failed to establish a new connection: [Errno 111] Connection refused')': /
[2022-03-30 16:45:54,586][urllib3.connectionpool][WARNING] - Retrying (Retry(total=3, connect=3, read=5, redirect=None, status=None)) after connection broken by 'NewConnectionError('<urllib3.connection.HTTPConnection object at 0x7f4b3e4eb5e0>: Failed to establish a new connection: [Errno 111] Connection refused')': /
[2022-03-30 16:46:22,170][root][ERROR] - Error
Traceback (most recent call last):
  File "/data/vision/torralba/frames/data_acquisition/SyntheticStories/agent_preferences/tshu/agent_preferences/analysis/helping_states.py", line 1310, in main
    print("main agent subgoal:", curr_info[0]["subgoals"])
  File "/data/vision/torralba/frames/data_acquisition/SyntheticStories/agent_preferences/tshu/agent_preferences/analysis/helping_states.py", line 1310, in main
    print("main agent subgoal:", curr_info[0]["subgoals"])
  File "/data/vision/torralba/frames/tools/anaconda3/envs/online_wah/lib/python3.9/bdb.py", line 88, in trace_dispatch
    return self.dispatch_line(frame)
  File "/data/vision/torralba/frames/tools/anaconda3/envs/online_wah/lib/python3.9/bdb.py", line 113, in dispatch_line
    if self.quitting: raise BdbQuit
bdb.BdbQuit
[2022-03-30 16:46:22,295][urllib3.connectionpool][WARNING] - Retrying (Retry(total=4, connect=4, read=5, redirect=None, status=None)) after connection broken by 'NewConnectionError('<urllib3.connection.HTTPConnection object at 0x7f4b11ff1820>: Failed to establish a new connection: [Errno 111] Connection refused')': /
[2022-03-30 16:53:11,592][urllib3.connectionpool][WARNING] - Retrying (Retry(total=4, connect=4, read=5, redirect=None, status=None)) after connection broken by 'NewConnectionError('<urllib3.connection.HTTPConnection object at 0x7fcbd246ad00>: Failed to establish a new connection: [Errno 111] Connection refused')': /
[2022-03-30 16:53:15,597][urllib3.connectionpool][WARNING] - Retrying (Retry(total=3, connect=3, read=5, redirect=None, status=None)) after connection broken by 'NewConnectionError('<urllib3.connection.HTTPConnection object at 0x7fcbd23ed2e0>: Failed to establish a new connection: [Errno 111] Connection refused')': /
[2022-03-30 17:04:33,595][root][ERROR] - Error
Traceback (most recent call last):
  File "/data/vision/torralba/frames/data_acquisition/SyntheticStories/agent_preferences/tshu/agent_preferences/analysis/helping_states.py", line 1544, in main
    < best_estimated_steps
  File "/data/vision/torralba/frames/data_acquisition/SyntheticStories/agent_preferences/tshu/agent_preferences/analysis/helping_states.py", line 1544, in main
    < best_estimated_steps
  File "/data/vision/torralba/frames/tools/anaconda3/envs/online_wah/lib/python3.9/bdb.py", line 88, in trace_dispatch
    return self.dispatch_line(frame)
  File "/data/vision/torralba/frames/tools/anaconda3/envs/online_wah/lib/python3.9/bdb.py", line 113, in dispatch_line
    if self.quitting: raise BdbQuit
bdb.BdbQuit
[2022-03-30 17:04:33,758][urllib3.connectionpool][WARNING] - Retrying (Retry(total=4, connect=4, read=5, redirect=None, status=None)) after connection broken by 'NewConnectionError('<urllib3.connection.HTTPConnection object at 0x7fcc217f1a60>: Failed to establish a new connection: [Errno 111] Connection refused')': /
[2022-03-30 17:05:03,608][urllib3.connectionpool][WARNING] - Retrying (Retry(total=4, connect=4, read=5, redirect=None, status=None)) after connection broken by 'NewConnectionError('<urllib3.connection.HTTPConnection object at 0x7ff367d7ef70>: Failed to establish a new connection: [Errno 111] Connection refused')': /
[2022-03-30 17:05:07,611][urllib3.connectionpool][WARNING] - Retrying (Retry(total=3, connect=3, read=5, redirect=None, status=None)) after connection broken by 'NewConnectionError('<urllib3.connection.HTTPConnection object at 0x7ff367d02610>: Failed to establish a new connection: [Errno 111] Connection refused')': /
[2022-03-30 17:05:30,239][root][ERROR] - Error
Traceback (most recent call last):
  File "/data/vision/torralba/frames/data_acquisition/SyntheticStories/agent_preferences/tshu/agent_preferences/analysis/helping_states.py", line 1479, in main
    dist = compute_dist_instance(
  File "/data/vision/torralba/frames/data_acquisition/SyntheticStories/agent_preferences/tshu/agent_preferences/analysis/helping_states.py", line 167, in compute_dist_instance
    edge_type, from_id, to_id = elements[0], int(elements[2]), int(elements[4])
ValueError: invalid literal for int() with base 10: 'coffeetable.247'
[2022-03-30 17:05:30,362][urllib3.connectionpool][WARNING] - Retrying (Retry(total=4, connect=4, read=5, redirect=None, status=None)) after connection broken by 'NewConnectionError('<urllib3.connection.HTTPConnection object at 0x7ff3a2e604f0>: Failed to establish a new connection: [Errno 111] Connection refused')': /
[2022-03-30 17:05:34,367][urllib3.connectionpool][WARNING] - Retrying (Retry(total=3, connect=3, read=5, redirect=None, status=None)) after connection broken by 'NewConnectionError('<urllib3.connection.HTTPConnection object at 0x7ff3a2e60640>: Failed to establish a new connection: [Errno 111] Connection refused')': /
[2022-03-30 17:06:54,277][urllib3.connectionpool][WARNING] - Retrying (Retry(total=4, connect=4, read=5, redirect=None, status=None)) after connection broken by 'NewConnectionError('<urllib3.connection.HTTPConnection object at 0x7f38ca0077f0>: Failed to establish a new connection: [Errno 111] Connection refused')': /
[2022-03-30 17:06:58,279][urllib3.connectionpool][WARNING] - Retrying (Retry(total=3, connect=3, read=5, redirect=None, status=None)) after connection broken by 'NewConnectionError('<urllib3.connection.HTTPConnection object at 0x7f38c9dd0640>: Failed to establish a new connection: [Errno 111] Connection refused')': /
[2022-03-30 17:09:29,863][root][ERROR] - Error
Traceback (most recent call last):
  File "/data/vision/torralba/frames/data_acquisition/SyntheticStories/agent_preferences/tshu/agent_preferences/analysis/helping_states.py", line 1578, in main
    )
  File "/data/vision/torralba/frames/data_acquisition/SyntheticStories/agent_preferences/tshu/agent_preferences/analysis/helping_states.py", line 1578, in main
    )
  File "/data/vision/torralba/frames/tools/anaconda3/envs/online_wah/lib/python3.9/bdb.py", line 88, in trace_dispatch
    return self.dispatch_line(frame)
  File "/data/vision/torralba/frames/tools/anaconda3/envs/online_wah/lib/python3.9/bdb.py", line 113, in dispatch_line
    if self.quitting: raise BdbQuit
bdb.BdbQuit
[2022-03-30 17:09:30,020][urllib3.connectionpool][WARNING] - Retrying (Retry(total=4, connect=4, read=5, redirect=None, status=None)) after connection broken by 'NewConnectionError('<urllib3.connection.HTTPConnection object at 0x7f391a177220>: Failed to establish a new connection: [Errno 111] Connection refused')': /
[2022-03-30 17:09:41,157][urllib3.connectionpool][WARNING] - Retrying (Retry(total=4, connect=4, read=5, redirect=None, status=None)) after connection broken by 'NewConnectionError('<urllib3.connection.HTTPConnection object at 0x7f1dfb547580>: Failed to establish a new connection: [Errno 111] Connection refused')': /
[2022-03-30 17:09:45,162][urllib3.connectionpool][WARNING] - Retrying (Retry(total=3, connect=3, read=5, redirect=None, status=None)) after connection broken by 'NewConnectionError('<urllib3.connection.HTTPConnection object at 0x7f1dfb547c10>: Failed to establish a new connection: [Errno 111] Connection refused')': /
[2022-03-30 17:10:28,462][urllib3.connectionpool][WARNING] - Retrying (Retry(total=4, connect=4, read=5, redirect=None, status=None)) after connection broken by 'NewConnectionError('<urllib3.connection.HTTPConnection object at 0x7fcdf6e146d0>: Failed to establish a new connection: [Errno 111] Connection refused')': /
[2022-03-30 17:10:32,467][urllib3.connectionpool][WARNING] - Retrying (Retry(total=3, connect=3, read=5, redirect=None, status=None)) after connection broken by 'NewConnectionError('<urllib3.connection.HTTPConnection object at 0x7fcdf6e14d60>: Failed to establish a new connection: [Errno 111] Connection refused')': /
[2022-03-30 17:11:02,105][root][ERROR] - Error
Traceback (most recent call last):
  File "/data/vision/torralba/frames/data_acquisition/SyntheticStories/agent_preferences/tshu/agent_preferences/analysis/helping_states.py", line 1491, in main
    dist = compute_dist_instance(
  File "/data/vision/torralba/frames/data_acquisition/SyntheticStories/agent_preferences/tshu/agent_preferences/analysis/helping_states.py", line 188, in compute_dist_instance
    curr_edge_class[edge_class] -= 1
KeyError: 'ON_chips_sofa'
[2022-03-30 17:11:02,238][urllib3.connectionpool][WARNING] - Retrying (Retry(total=4, connect=4, read=5, redirect=None, status=None)) after connection broken by 'NewConnectionError('<urllib3.connection.HTTPConnection object at 0x7fce45e5ba60>: Failed to establish a new connection: [Errno 111] Connection refused')': /
[2022-03-30 17:11:06,243][urllib3.connectionpool][WARNING] - Retrying (Retry(total=3, connect=3, read=5, redirect=None, status=None)) after connection broken by 'NewConnectionError('<urllib3.connection.HTTPConnection object at 0x7fce45e5b910>: Failed to establish a new connection: [Errno 111] Connection refused')': /
[2022-03-30 17:11:32,065][urllib3.connectionpool][WARNING] - Retrying (Retry(total=4, connect=4, read=5, redirect=None, status=None)) after connection broken by 'NewConnectionError('<urllib3.connection.HTTPConnection object at 0x7fbdfe721580>: Failed to establish a new connection: [Errno 111] Connection refused')': /
[2022-03-30 17:11:36,067][urllib3.connectionpool][WARNING] - Retrying (Retry(total=3, connect=3, read=5, redirect=None, status=None)) after connection broken by 'NewConnectionError('<urllib3.connection.HTTPConnection object at 0x7fbdfe721c10>: Failed to establish a new connection: [Errno 111] Connection refused')': /
[2022-03-30 17:14:08,552][root][ERROR] - Error
Traceback (most recent call last):
  File "/data/vision/torralba/frames/data_acquisition/SyntheticStories/agent_preferences/tshu/agent_preferences/analysis/helping_states.py", line 1584, in main
  File "/data/vision/torralba/frames/data_acquisition/SyntheticStories/agent_preferences/tshu/agent_preferences/analysis/helping_states.py", line 1584, in main
  File "/data/vision/torralba/frames/tools/anaconda3/envs/online_wah/lib/python3.9/bdb.py", line 88, in trace_dispatch
    return self.dispatch_line(frame)
  File "/data/vision/torralba/frames/tools/anaconda3/envs/online_wah/lib/python3.9/bdb.py", line 113, in dispatch_line
    if self.quitting: raise BdbQuit
bdb.BdbQuit
[2022-03-30 17:14:08,706][urllib3.connectionpool][WARNING] - Retrying (Retry(total=4, connect=4, read=5, redirect=None, status=None)) after connection broken by 'NewConnectionError('<urllib3.connection.HTTPConnection object at 0x7fbdfe6eeb80>: Failed to establish a new connection: [Errno 111] Connection refused')': /
[2022-03-30 17:14:20,560][urllib3.connectionpool][WARNING] - Retrying (Retry(total=4, connect=4, read=5, redirect=None, status=None)) after connection broken by 'NewConnectionError('<urllib3.connection.HTTPConnection object at 0x7fdf6990dfa0>: Failed to establish a new connection: [Errno 111] Connection refused')': /
[2022-03-30 17:14:24,563][urllib3.connectionpool][WARNING] - Retrying (Retry(total=3, connect=3, read=5, redirect=None, status=None)) after connection broken by 'NewConnectionError('<urllib3.connection.HTTPConnection object at 0x7fdf6993ddc0>: Failed to establish a new connection: [Errno 111] Connection refused')': /
[2022-03-30 17:17:23,080][root][ERROR] - Error
Traceback (most recent call last):
  File "/data/vision/torralba/frames/data_acquisition/SyntheticStories/agent_preferences/tshu/agent_preferences/analysis/helping_states.py", line 1585, in main
    ipdb.set_trace()
  File "/data/vision/torralba/frames/data_acquisition/SyntheticStories/agent_preferences/tshu/agent_preferences/analysis/helping_states.py", line 1585, in main
    ipdb.set_trace()
  File "/data/vision/torralba/frames/tools/anaconda3/envs/online_wah/lib/python3.9/bdb.py", line 88, in trace_dispatch
    return self.dispatch_line(frame)
  File "/data/vision/torralba/frames/tools/anaconda3/envs/online_wah/lib/python3.9/bdb.py", line 113, in dispatch_line
    if self.quitting: raise BdbQuit
bdb.BdbQuit
[2022-03-30 17:17:23,224][urllib3.connectionpool][WARNING] - Retrying (Retry(total=4, connect=4, read=5, redirect=None, status=None)) after connection broken by 'NewConnectionError('<urllib3.connection.HTTPConnection object at 0x7fdfba1f12e0>: Failed to establish a new connection: [Errno 111] Connection refused')': /
[2022-03-30 17:17:35,418][urllib3.connectionpool][WARNING] - Retrying (Retry(total=4, connect=4, read=5, redirect=None, status=None)) after connection broken by 'NewConnectionError('<urllib3.connection.HTTPConnection object at 0x7f4ea1ee9fd0>: Failed to establish a new connection: [Errno 111] Connection refused')': /
[2022-03-30 17:17:39,422][urllib3.connectionpool][WARNING] - Retrying (Retry(total=3, connect=3, read=5, redirect=None, status=None)) after connection broken by 'NewConnectionError('<urllib3.connection.HTTPConnection object at 0x7f4ea1eef6d0>: Failed to establish a new connection: [Errno 111] Connection refused')': /
[2022-03-30 17:21:22,554][root][ERROR] - Error
Traceback (most recent call last):
  File "/data/vision/torralba/frames/data_acquisition/SyntheticStories/agent_preferences/tshu/agent_preferences/analysis/helping_states.py", line 1587, in main
  File "/data/vision/torralba/frames/data_acquisition/SyntheticStories/agent_preferences/tshu/agent_preferences/analysis/helping_states.py", line 1587, in main
  File "/data/vision/torralba/frames/tools/anaconda3/envs/online_wah/lib/python3.9/bdb.py", line 88, in trace_dispatch
    return self.dispatch_line(frame)
  File "/data/vision/torralba/frames/tools/anaconda3/envs/online_wah/lib/python3.9/bdb.py", line 113, in dispatch_line
    if self.quitting: raise BdbQuit
bdb.BdbQuit
[2022-03-30 17:21:22,711][urllib3.connectionpool][WARNING] - Retrying (Retry(total=4, connect=4, read=5, redirect=None, status=None)) after connection broken by 'NewConnectionError('<urllib3.connection.HTTPConnection object at 0x7f4ef163b280>: Failed to establish a new connection: [Errno 111] Connection refused')': /
[2022-03-30 17:21:56,639][urllib3.connectionpool][WARNING] - Retrying (Retry(total=4, connect=4, read=5, redirect=None, status=None)) after connection broken by 'NewConnectionError('<urllib3.connection.HTTPConnection object at 0x7fc0753f4880>: Failed to establish a new connection: [Errno 111] Connection refused')': /
[2022-03-30 17:22:00,643][urllib3.connectionpool][WARNING] - Retrying (Retry(total=3, connect=3, read=5, redirect=None, status=None)) after connection broken by 'NewConnectionError('<urllib3.connection.HTTPConnection object at 0x7fc0753f42e0>: Failed to establish a new connection: [Errno 111] Connection refused')': /
[2022-03-30 17:22:24,236][root][ERROR] - Error
Traceback (most recent call last):
  File "/data/vision/torralba/frames/data_acquisition/SyntheticStories/agent_preferences/tshu/agent_preferences/analysis/helping_states.py", line 1523, in main
    dist,
UnboundLocalError: local variable 'dist' referenced before assignment
[2022-03-30 17:22:24,355][urllib3.connectionpool][WARNING] - Retrying (Retry(total=4, connect=4, read=5, redirect=None, status=None)) after connection broken by 'NewConnectionError('<urllib3.connection.HTTPConnection object at 0x7fc0c442b5b0>: Failed to establish a new connection: [Errno 111] Connection refused')': /
[2022-03-30 17:22:28,359][urllib3.connectionpool][WARNING] - Retrying (Retry(total=3, connect=3, read=5, redirect=None, status=None)) after connection broken by 'NewConnectionError('<urllib3.connection.HTTPConnection object at 0x7fc0c442b820>: Failed to establish a new connection: [Errno 111] Connection refused')': /
[2022-03-30 17:24:09,794][urllib3.connectionpool][WARNING] - Retrying (Retry(total=4, connect=4, read=5, redirect=None, status=None)) after connection broken by 'NewConnectionError('<urllib3.connection.HTTPConnection object at 0x7f8eff772040>: Failed to establish a new connection: [Errno 111] Connection refused')': /
[2022-03-30 17:24:13,799][urllib3.connectionpool][WARNING] - Retrying (Retry(total=3, connect=3, read=5, redirect=None, status=None)) after connection broken by 'NewConnectionError('<urllib3.connection.HTTPConnection object at 0x7f8eff772610>: Failed to establish a new connection: [Errno 111] Connection refused')': /
[2022-03-30 17:25:44,969][root][ERROR] - Error
Traceback (most recent call last):
  File "/data/vision/torralba/frames/data_acquisition/SyntheticStories/agent_preferences/tshu/agent_preferences/analysis/helping_states.py", line 1491, in main
    estimated_steps += max(int(cost + 0.5), 1)
  File "/data/vision/torralba/frames/data_acquisition/SyntheticStories/agent_preferences/tshu/agent_preferences/analysis/helping_states.py", line 215, in compute_dist_instance
    ipdb.set_trace()
  File "/data/vision/torralba/frames/data_acquisition/SyntheticStories/agent_preferences/tshu/agent_preferences/analysis/helping_states.py", line 215, in compute_dist_instance
    ipdb.set_trace()
  File "/data/vision/torralba/frames/tools/anaconda3/envs/online_wah/lib/python3.9/bdb.py", line 88, in trace_dispatch
    return self.dispatch_line(frame)
  File "/data/vision/torralba/frames/tools/anaconda3/envs/online_wah/lib/python3.9/bdb.py", line 113, in dispatch_line
    if self.quitting: raise BdbQuit
bdb.BdbQuit
[2022-03-30 17:25:45,112][urllib3.connectionpool][WARNING] - Retrying (Retry(total=4, connect=4, read=5, redirect=None, status=None)) after connection broken by 'NewConnectionError('<urllib3.connection.HTTPConnection object at 0x7f8f4cddfe20>: Failed to establish a new connection: [Errno 111] Connection refused')': /
[2022-03-30 17:25:58,437][urllib3.connectionpool][WARNING] - Retrying (Retry(total=4, connect=4, read=5, redirect=None, status=None)) after connection broken by 'NewConnectionError('<urllib3.connection.HTTPConnection object at 0x7fb2707b3160>: Failed to establish a new connection: [Errno 111] Connection refused')': /
[2022-03-30 17:26:02,439][urllib3.connectionpool][WARNING] - Retrying (Retry(total=3, connect=3, read=5, redirect=None, status=None)) after connection broken by 'NewConnectionError('<urllib3.connection.HTTPConnection object at 0x7fb2707b37f0>: Failed to establish a new connection: [Errno 111] Connection refused')': /
[2022-03-30 17:28:58,214][root][ERROR] - Error
Traceback (most recent call last):
  File "/data/vision/torralba/frames/data_acquisition/SyntheticStories/agent_preferences/tshu/agent_preferences/analysis/helping_states.py", line 1587, in main
    # ipdb.set_trace()
  File "/data/vision/torralba/frames/data_acquisition/SyntheticStories/agent_preferences/tshu/agent_preferences/analysis/helping_states.py", line 1587, in main
    # ipdb.set_trace()
  File "/data/vision/torralba/frames/tools/anaconda3/envs/online_wah/lib/python3.9/bdb.py", line 88, in trace_dispatch
    return self.dispatch_line(frame)
  File "/data/vision/torralba/frames/tools/anaconda3/envs/online_wah/lib/python3.9/bdb.py", line 113, in dispatch_line
    if self.quitting: raise BdbQuit
bdb.BdbQuit
[2022-03-30 17:28:58,363][urllib3.connectionpool][WARNING] - Retrying (Retry(total=4, connect=4, read=5, redirect=None, status=None)) after connection broken by 'NewConnectionError('<urllib3.connection.HTTPConnection object at 0x7fb2c01c9eb0>: Failed to establish a new connection: [Errno 111] Connection refused')': /
[2022-03-30 17:29:09,675][urllib3.connectionpool][WARNING] - Retrying (Retry(total=4, connect=4, read=5, redirect=None, status=None)) after connection broken by 'NewConnectionError('<urllib3.connection.HTTPConnection object at 0x7f37589430a0>: Failed to establish a new connection: [Errno 111] Connection refused')': /
[2022-03-30 17:29:13,680][urllib3.connectionpool][WARNING] - Retrying (Retry(total=3, connect=3, read=5, redirect=None, status=None)) after connection broken by 'NewConnectionError('<urllib3.connection.HTTPConnection object at 0x7f3758943730>: Failed to establish a new connection: [Errno 111] Connection refused')': /
[2022-03-30 17:31:27,318][urllib3.connectionpool][WARNING] - Retrying (Retry(total=4, connect=4, read=5, redirect=None, status=None)) after connection broken by 'NewConnectionError('<urllib3.connection.HTTPConnection object at 0x7f4849194d30>: Failed to establish a new connection: [Errno 111] Connection refused')': /
[2022-03-30 17:31:31,323][urllib3.connectionpool][WARNING] - Retrying (Retry(total=3, connect=3, read=5, redirect=None, status=None)) after connection broken by 'NewConnectionError('<urllib3.connection.HTTPConnection object at 0x7f48491945b0>: Failed to establish a new connection: [Errno 111] Connection refused')': /
[2022-03-30 17:31:56,892][root][ERROR] - Error
Traceback (most recent call last):
  File "/data/vision/torralba/frames/data_acquisition/SyntheticStories/agent_preferences/tshu/agent_preferences/analysis/helping_states.py", line 1318, in main
    selected_actions, curr_info = arena.get_actions(
  File "/data/vision/torralba/frames/data_acquisition/SyntheticStories/agent_preferences/tshu/agent_preferences/algos/arena_mp2.py", line 127, in get_actions
    dict_actions[it], dict_info[it] = agent.get_action(
  File "/data/vision/torralba/frames/data_acquisition/SyntheticStories/agent_preferences/tshu/agent_preferences/agents/MCTS_agent_particle_v2_instance.py", line 1179, in get_action
    plan, root_node, subgoals = get_plan(
  File "/data/vision/torralba/frames/data_acquisition/SyntheticStories/agent_preferences/tshu/agent_preferences/agents/MCTS_agent_particle_v2_instance.py", line 721, in get_plan
    info = [mp_run(rn) for rn in root_nodes]
  File "/data/vision/torralba/frames/data_acquisition/SyntheticStories/agent_preferences/tshu/agent_preferences/utils/utils_exception.py", line 24, in re_raise
    raise self.ee.with_traceback(self.tb)
  File "/data/vision/torralba/frames/data_acquisition/SyntheticStories/agent_preferences/tshu/agent_preferences/agents/MCTS_agent_particle_v2_instance.py", line 627, in mp_run_mcts
    res = new_mcts.run(
  File "/data/vision/torralba/frames/data_acquisition/SyntheticStories/agent_preferences/tshu/agent_preferences/MCTS/MCTS_particles_v2_instance.py", line 280, in run
    value, reward_rollout, actions_rollout = self.rollout(
  File "/data/vision/torralba/frames/data_acquisition/SyntheticStories/agent_preferences/tshu/agent_preferences/MCTS/MCTS_particles_v2_instance.py", line 532, in rollout
    ) = self.transition(
  File "/data/vision/torralba/frames/data_acquisition/SyntheticStories/agent_preferences/tshu/agent_preferences/MCTS/MCTS_particles_v2_instance.py", line 685, in transition
    success, next_vh_state = self.env.transition(curr_vh_state, action)
  File "/data/vision/torralba/frames/data_acquisition/SyntheticStories/agent_preferences/tshu/agent_preferences/envs/graph_env.py", line 532, in transition
    next_vh_state = init_from_state(
  File "/data/vision/torralba/frames/data_acquisition/SyntheticStories/agent_preferences/tshu/agent_preferences/envs/graph_env.py", line 532, in transition
    next_vh_state = init_from_state(
  File "/data/vision/torralba/frames/tools/anaconda3/envs/online_wah/lib/python3.9/bdb.py", line 88, in trace_dispatch
    return self.dispatch_line(frame)
  File "/data/vision/torralba/frames/tools/anaconda3/envs/online_wah/lib/python3.9/bdb.py", line 113, in dispatch_line
    if self.quitting: raise BdbQuit
bdb.BdbQuit
[2022-03-30 17:31:57,024][urllib3.connectionpool][WARNING] - Retrying (Retry(total=4, connect=4, read=5, redirect=None, status=None)) after connection broken by 'NewConnectionError('<urllib3.connection.HTTPConnection object at 0x7f4898971a60>: Failed to establish a new connection: [Errno 111] Connection refused')': /
[2022-03-30 17:33:14,974][urllib3.connectionpool][WARNING] - Retrying (Retry(total=4, connect=4, read=5, redirect=None, status=None)) after connection broken by 'NewConnectionError('<urllib3.connection.HTTPConnection object at 0x7f83e6792400>: Failed to establish a new connection: [Errno 111] Connection refused')': /
[2022-03-30 17:33:18,975][urllib3.connectionpool][WARNING] - Retrying (Retry(total=3, connect=3, read=5, redirect=None, status=None)) after connection broken by 'NewConnectionError('<urllib3.connection.HTTPConnection object at 0x7f83e6792a90>: Failed to establish a new connection: [Errno 111] Connection refused')': /
[2022-03-30 17:37:29,226][root][ERROR] - Error
Traceback (most recent call last):
  File "/data/vision/torralba/frames/data_acquisition/SyntheticStories/agent_preferences/tshu/agent_preferences/analysis/helping_states.py", line 1504, in main
    # else:
  File "/data/vision/torralba/frames/data_acquisition/SyntheticStories/agent_preferences/tshu/agent_preferences/analysis/helping_states.py", line 228, in compute_dist_instance
    if dist == 1 and edge_type in ["on", "inside"]:
  File "/data/vision/torralba/frames/data_acquisition/SyntheticStories/agent_preferences/tshu/agent_preferences/analysis/helping_states.py", line 228, in compute_dist_instance
    if dist == 1 and edge_type in ["on", "inside"]:
  File "/data/vision/torralba/frames/tools/anaconda3/envs/online_wah/lib/python3.9/bdb.py", line 88, in trace_dispatch
    return self.dispatch_line(frame)
  File "/data/vision/torralba/frames/tools/anaconda3/envs/online_wah/lib/python3.9/bdb.py", line 113, in dispatch_line
    if self.quitting: raise BdbQuit
bdb.BdbQuit
[2022-03-30 17:37:29,358][urllib3.connectionpool][WARNING] - Retrying (Retry(total=4, connect=4, read=5, redirect=None, status=None)) after connection broken by 'NewConnectionError('<urllib3.connection.HTTPConnection object at 0x7f84339f4d00>: Failed to establish a new connection: [Errno 111] Connection refused')': /
[2022-03-30 17:37:51,956][urllib3.connectionpool][WARNING] - Retrying (Retry(total=4, connect=4, read=5, redirect=None, status=None)) after connection broken by 'NewConnectionError('<urllib3.connection.HTTPConnection object at 0x7f14fe1fe550>: Failed to establish a new connection: [Errno 111] Connection refused')': /
[2022-03-30 17:37:55,959][urllib3.connectionpool][WARNING] - Retrying (Retry(total=3, connect=3, read=5, redirect=None, status=None)) after connection broken by 'NewConnectionError('<urllib3.connection.HTTPConnection object at 0x7f14fe1febe0>: Failed to establish a new connection: [Errno 111] Connection refused')': /
[2022-03-30 17:39:19,207][urllib3.connectionpool][WARNING] - Retrying (Retry(total=4, connect=4, read=5, redirect=None, status=None)) after connection broken by 'NewConnectionError('<urllib3.connection.HTTPConnection object at 0x7fc4ebf7ed60>: Failed to establish a new connection: [Errno 111] Connection refused')': /
[2022-03-30 17:39:23,211][urllib3.connectionpool][WARNING] - Retrying (Retry(total=3, connect=3, read=5, redirect=None, status=None)) after connection broken by 'NewConnectionError('<urllib3.connection.HTTPConnection object at 0x7fc4ebf83340>: Failed to establish a new connection: [Errno 111] Connection refused')': /
[2022-03-31 17:18:31,827][urllib3.connectionpool][WARNING] - Retrying (Retry(total=4, connect=4, read=5, redirect=None, status=None)) after connection broken by 'NewConnectionError('<urllib3.connection.HTTPConnection object at 0x7fdf252787c0>: Failed to establish a new connection: [Errno 111] Connection refused')': /
[2022-03-31 17:18:35,832][urllib3.connectionpool][WARNING] - Retrying (Retry(total=3, connect=3, read=5, redirect=None, status=None)) after connection broken by 'NewConnectionError('<urllib3.connection.HTTPConnection object at 0x7fdf25278a60>: Failed to establish a new connection: [Errno 111] Connection refused')': /
[2022-03-31 17:18:43,839][urllib3.connectionpool][WARNING] - Retrying (Retry(total=2, connect=2, read=5, redirect=None, status=None)) after connection broken by 'NewConnectionError('<urllib3.connection.HTTPConnection object at 0x7fdf25278c70>: Failed to establish a new connection: [Errno 111] Connection refused')': /
[2022-03-31 17:19:56,587][urllib3.connectionpool][WARNING] - Retrying (Retry(total=4, connect=4, read=5, redirect=None, status=None)) after connection broken by 'NewConnectionError('<urllib3.connection.HTTPConnection object at 0x7f741c7ea7c0>: Failed to establish a new connection: [Errno 111] Connection refused')': /
[2022-03-31 17:20:00,592][urllib3.connectionpool][WARNING] - Retrying (Retry(total=3, connect=3, read=5, redirect=None, status=None)) after connection broken by 'NewConnectionError('<urllib3.connection.HTTPConnection object at 0x7f741c7eaa60>: Failed to establish a new connection: [Errno 111] Connection refused')': /
[2022-03-31 17:20:22,006][urllib3.connectionpool][WARNING] - Retrying (Retry(total=4, connect=4, read=5, redirect=None, status=None)) after connection broken by 'NewConnectionError('<urllib3.connection.HTTPConnection object at 0x7fa0d7e70820>: Failed to establish a new connection: [Errno 111] Connection refused')': /
[2022-03-31 17:20:26,011][urllib3.connectionpool][WARNING] - Retrying (Retry(total=3, connect=3, read=5, redirect=None, status=None)) after connection broken by 'NewConnectionError('<urllib3.connection.HTTPConnection object at 0x7fa0d7e70ac0>: Failed to establish a new connection: [Errno 111] Connection refused')': /
[2022-03-31 17:22:05,689][root][ERROR] - Error
Traceback (most recent call last):
  File "/data/vision/torralba/frames/data_acquisition/SyntheticStories/agent_preferences/tshu/agent_preferences/analysis/helping_states.py", line 1604, in main
    edge_pred_class_estimated = aggregate_multiple_pred(
  File "/data/vision/torralba/frames/data_acquisition/SyntheticStories/agent_preferences/tshu/agent_preferences/analysis/helping_states.py", line 1604, in main
    edge_pred_class_estimated = aggregate_multiple_pred(
  File "/data/vision/torralba/frames/tools/anaconda3/envs/online_wah/lib/python3.9/bdb.py", line 88, in trace_dispatch
    return self.dispatch_line(frame)
  File "/data/vision/torralba/frames/tools/anaconda3/envs/online_wah/lib/python3.9/bdb.py", line 113, in dispatch_line
    if self.quitting: raise BdbQuit
bdb.BdbQuit
[2022-03-31 17:22:05,795][urllib3.connectionpool][WARNING] - Retrying (Retry(total=4, connect=4, read=5, redirect=None, status=None)) after connection broken by 'NewConnectionError('<urllib3.connection.HTTPConnection object at 0x7fa115960760>: Failed to establish a new connection: [Errno 111] Connection refused')': /
[2022-03-31 17:22:19,540][urllib3.connectionpool][WARNING] - Retrying (Retry(total=4, connect=4, read=5, redirect=None, status=None)) after connection broken by 'NewConnectionError('<urllib3.connection.HTTPConnection object at 0x7f6d7b000790>: Failed to establish a new connection: [Errno 111] Connection refused')': /
[2022-03-31 17:22:23,543][urllib3.connectionpool][WARNING] - Retrying (Retry(total=3, connect=3, read=5, redirect=None, status=None)) after connection broken by 'NewConnectionError('<urllib3.connection.HTTPConnection object at 0x7f6d7b000a30>: Failed to establish a new connection: [Errno 111] Connection refused')': /
[2022-03-31 17:27:49,477][root][ERROR] - Error
Traceback (most recent call last):
  File "/data/vision/torralba/frames/data_acquisition/SyntheticStories/agent_preferences/tshu/agent_preferences/analysis/helping_states.py", line 1604, in main
    edge_pred_class_estimated = aggregate_multiple_pred(
  File "/data/vision/torralba/frames/data_acquisition/SyntheticStories/agent_preferences/tshu/agent_preferences/analysis/helping_states.py", line 1604, in main
    edge_pred_class_estimated = aggregate_multiple_pred(
  File "/data/vision/torralba/frames/tools/anaconda3/envs/online_wah/lib/python3.9/bdb.py", line 88, in trace_dispatch
    return self.dispatch_line(frame)
  File "/data/vision/torralba/frames/tools/anaconda3/envs/online_wah/lib/python3.9/bdb.py", line 113, in dispatch_line
    if self.quitting: raise BdbQuit
bdb.BdbQuit
[2022-03-31 17:27:49,612][urllib3.connectionpool][WARNING] - Retrying (Retry(total=4, connect=4, read=5, redirect=None, status=None)) after connection broken by 'NewConnectionError('<urllib3.connection.HTTPConnection object at 0x7f6dca473fa0>: Failed to establish a new connection: [Errno 111] Connection refused')': /
[2022-03-31 17:28:02,825][urllib3.connectionpool][WARNING] - Retrying (Retry(total=4, connect=4, read=5, redirect=None, status=None)) after connection broken by 'NewConnectionError('<urllib3.connection.HTTPConnection object at 0x7fe427dc5790>: Failed to establish a new connection: [Errno 111] Connection refused')': /
[2022-03-31 17:28:06,827][urllib3.connectionpool][WARNING] - Retrying (Retry(total=3, connect=3, read=5, redirect=None, status=None)) after connection broken by 'NewConnectionError('<urllib3.connection.HTTPConnection object at 0x7fe427dc5a30>: Failed to establish a new connection: [Errno 111] Connection refused')': /
[2022-03-31 17:34:05,642][root][ERROR] - Error
Traceback (most recent call last):
  File "/data/vision/torralba/frames/data_acquisition/SyntheticStories/agent_preferences/tshu/agent_preferences/analysis/helping_states.py", line 1602, in main
    ipdb.set_trace()
  File "/data/vision/torralba/frames/data_acquisition/SyntheticStories/agent_preferences/tshu/agent_preferences/analysis/helping_states.py", line 1602, in main
    ipdb.set_trace()
  File "/data/vision/torralba/frames/tools/anaconda3/envs/online_wah/lib/python3.9/bdb.py", line 88, in trace_dispatch
    return self.dispatch_line(frame)
  File "/data/vision/torralba/frames/tools/anaconda3/envs/online_wah/lib/python3.9/bdb.py", line 113, in dispatch_line
    if self.quitting: raise BdbQuit
bdb.BdbQuit
[2022-03-31 17:34:05,769][urllib3.connectionpool][WARNING] - Retrying (Retry(total=4, connect=4, read=5, redirect=None, status=None)) after connection broken by 'NewConnectionError('<urllib3.connection.HTTPConnection object at 0x7fe30c0fc400>: Failed to establish a new connection: [Errno 111] Connection refused')': /
[2022-03-31 17:34:21,672][urllib3.connectionpool][WARNING] - Retrying (Retry(total=4, connect=4, read=5, redirect=None, status=None)) after connection broken by 'NewConnectionError('<urllib3.connection.HTTPConnection object at 0x7f66ca3ad790>: Failed to establish a new connection: [Errno 111] Connection refused')': /
[2022-03-31 17:34:25,675][urllib3.connectionpool][WARNING] - Retrying (Retry(total=3, connect=3, read=5, redirect=None, status=None)) after connection broken by 'NewConnectionError('<urllib3.connection.HTTPConnection object at 0x7f66ca3ada30>: Failed to establish a new connection: [Errno 111] Connection refused')': /
[2022-03-31 17:36:09,985][root][ERROR] - Error
Traceback (most recent call last):
  File "/data/vision/torralba/frames/data_acquisition/SyntheticStories/agent_preferences/tshu/agent_preferences/analysis/helping_states.py", line 1604, in main
    edge_pred_class_estimated = aggregate_multiple_pred(
NameError: name 'gt_goals' is not defined
[2022-03-31 17:36:10,123][urllib3.connectionpool][WARNING] - Retrying (Retry(total=4, connect=4, read=5, redirect=None, status=None)) after connection broken by 'NewConnectionError('<urllib3.connection.HTTPConnection object at 0x7f669eb85220>: Failed to establish a new connection: [Errno 111] Connection refused')': /
[2022-03-31 17:36:14,128][urllib3.connectionpool][WARNING] - Retrying (Retry(total=3, connect=3, read=5, redirect=None, status=None)) after connection broken by 'NewConnectionError('<urllib3.connection.HTTPConnection object at 0x7f669eb85d30>: Failed to establish a new connection: [Errno 111] Connection refused')': /
[2022-03-31 17:36:22,223][root][ERROR] - Error
Traceback (most recent call last):
  File "/data/vision/torralba/frames/data_acquisition/SyntheticStories/agent_preferences/tshu/agent_preferences/analysis/helping_states.py", line 1604, in main
    edge_pred_class_estimated = aggregate_multiple_pred(
  File "/data/vision/torralba/frames/data_acquisition/SyntheticStories/agent_preferences/tshu/agent_preferences/algos/arena_mp2.py", line 127, in get_actions
    dict_actions[it], dict_info[it] = agent.get_action(
  File "/data/vision/torralba/frames/data_acquisition/SyntheticStories/agent_preferences/tshu/agent_preferences/agents/MCTS_agent_particle_v2_instance.py", line 1179, in get_action
    plan, root_node, subgoals = get_plan(
  File "/data/vision/torralba/frames/data_acquisition/SyntheticStories/agent_preferences/tshu/agent_preferences/agents/MCTS_agent_particle_v2_instance.py", line 721, in get_plan
    info = [mp_run(rn) for rn in root_nodes]
  File "/data/vision/torralba/frames/data_acquisition/SyntheticStories/agent_preferences/tshu/agent_preferences/utils/utils_exception.py", line 24, in re_raise
    raise self.ee.with_traceback(self.tb)
  File "/data/vision/torralba/frames/data_acquisition/SyntheticStories/agent_preferences/tshu/agent_preferences/agents/MCTS_agent_particle_v2_instance.py", line 627, in mp_run_mcts
    res = new_mcts.run(
  File "/data/vision/torralba/frames/data_acquisition/SyntheticStories/agent_preferences/tshu/agent_preferences/MCTS/MCTS_particles_v2_instance.py", line 125, in run
    self.env = VhGraphEnv(n_chars=self.char_index + 1)
  File "/data/vision/torralba/frames/data_acquisition/SyntheticStories/agent_preferences/tshu/agent_preferences/envs/graph_env.py", line 148, in __init__
    self.graph_helper = graph_dict_helper()
  File "/data/vision/torralba/frames/data_acquisition/SyntheticStories/agent_preferences/tshu/agent_preferences/envs/../../virtualhome/simulation/evolving_graph/utils.py", line 255, in __init__
    self.unity_object2script_object = build_unity2object_script(self.script_object2unity_object)
  File "/data/vision/torralba/frames/data_acquisition/SyntheticStories/agent_preferences/tshu/agent_preferences/envs/../../virtualhome/simulation/evolving_graph/utils.py", line 153, in build_unity2object_script
    for child in children_source: unity_object2script_object[child] = dest_parent
  File "/data/vision/torralba/frames/data_acquisition/SyntheticStories/agent_preferences/tshu/agent_preferences/envs/../../virtualhome/simulation/evolving_graph/utils.py", line 153, in build_unity2object_script
    for child in children_source: unity_object2script_object[child] = dest_parent
  File "/data/vision/torralba/frames/tools/anaconda3/envs/online_wah/lib/python3.9/bdb.py", line 88, in trace_dispatch
    return self.dispatch_line(frame)
  File "/data/vision/torralba/frames/tools/anaconda3/envs/online_wah/lib/python3.9/bdb.py", line 113, in dispatch_line
    if self.quitting: raise BdbQuit
bdb.BdbQuit
[2022-03-31 17:36:34,768][urllib3.connectionpool][WARNING] - Retrying (Retry(total=4, connect=4, read=5, redirect=None, status=None)) after connection broken by 'NewConnectionError('<urllib3.connection.HTTPConnection object at 0x7f3ea74107c0>: Failed to establish a new connection: [Errno 111] Connection refused')': /
[2022-03-31 17:36:38,771][urllib3.connectionpool][WARNING] - Retrying (Retry(total=3, connect=3, read=5, redirect=None, status=None)) after connection broken by 'NewConnectionError('<urllib3.connection.HTTPConnection object at 0x7f3ea7410a60>: Failed to establish a new connection: [Errno 111] Connection refused')': /
[2022-03-31 17:41:22,568][root][ERROR] - Error
Traceback (most recent call last):
  File "/data/vision/torralba/frames/data_acquisition/SyntheticStories/agent_preferences/tshu/agent_preferences/analysis/helping_states.py", line 1669, in main
    if infos["finished"]:
  File "/data/vision/torralba/frames/data_acquisition/SyntheticStories/agent_preferences/tshu/agent_preferences/analysis/helping_states.py", line 1669, in main
    if infos["finished"]:
  File "/data/vision/torralba/frames/tools/anaconda3/envs/online_wah/lib/python3.9/bdb.py", line 88, in trace_dispatch
    return self.dispatch_line(frame)
  File "/data/vision/torralba/frames/tools/anaconda3/envs/online_wah/lib/python3.9/bdb.py", line 113, in dispatch_line
    if self.quitting: raise BdbQuit
bdb.BdbQuit
[2022-03-31 17:41:22,694][urllib3.connectionpool][WARNING] - Retrying (Retry(total=4, connect=4, read=5, redirect=None, status=None)) after connection broken by 'NewConnectionError('<urllib3.connection.HTTPConnection object at 0x7f3ea8061460>: Failed to establish a new connection: [Errno 111] Connection refused')': /
[2022-03-31 17:41:41,527][urllib3.connectionpool][WARNING] - Retrying (Retry(total=4, connect=4, read=5, redirect=None, status=None)) after connection broken by 'NewConnectionError('<urllib3.connection.HTTPConnection object at 0x7f258c42f7f0>: Failed to establish a new connection: [Errno 111] Connection refused')': /
[2022-03-31 17:41:45,532][urllib3.connectionpool][WARNING] - Retrying (Retry(total=3, connect=3, read=5, redirect=None, status=None)) after connection broken by 'NewConnectionError('<urllib3.connection.HTTPConnection object at 0x7f258c42fa90>: Failed to establish a new connection: [Errno 111] Connection refused')': /
[2022-03-31 18:06:51,367][root][ERROR] - Error
Traceback (most recent call last):
  File "/data/vision/torralba/frames/data_acquisition/SyntheticStories/agent_preferences/tshu/agent_preferences/analysis/helping_states.py", line 1669, in main
    pdb.set_trace()
  File "/data/vision/torralba/frames/tools/anaconda3/envs/online_wah/lib/python3.9/multiprocessing/process.py", line 149, in join
    res = self._popen.wait(timeout)
  File "/data/vision/torralba/frames/tools/anaconda3/envs/online_wah/lib/python3.9/multiprocessing/popen_fork.py", line 43, in wait
    return self.poll(os.WNOHANG if timeout == 0.0 else 0)
  File "/data/vision/torralba/frames/tools/anaconda3/envs/online_wah/lib/python3.9/multiprocessing/popen_fork.py", line 32, in poll
    if pid == self.pid:
  File "/data/vision/torralba/frames/tools/anaconda3/envs/online_wah/lib/python3.9/multiprocessing/popen_fork.py", line 32, in poll
    if pid == self.pid:
  File "/data/vision/torralba/frames/tools/anaconda3/envs/online_wah/lib/python3.9/bdb.py", line 88, in trace_dispatch
    return self.dispatch_line(frame)
  File "/data/vision/torralba/frames/tools/anaconda3/envs/online_wah/lib/python3.9/bdb.py", line 113, in dispatch_line
    if self.quitting: raise BdbQuit
bdb.BdbQuit
[2022-03-31 18:22:23,447][urllib3.connectionpool][WARNING] - Retrying (Retry(total=4, connect=4, read=5, redirect=None, status=None)) after connection broken by 'NewConnectionError('<urllib3.connection.HTTPConnection object at 0x7f61aa382760>: Failed to establish a new connection: [Errno 111] Connection refused')': /
[2022-03-31 18:22:27,451][urllib3.connectionpool][WARNING] - Retrying (Retry(total=3, connect=3, read=5, redirect=None, status=None)) after connection broken by 'NewConnectionError('<urllib3.connection.HTTPConnection object at 0x7f61aa382a00>: Failed to establish a new connection: [Errno 111] Connection refused')': /
[2022-03-31 18:25:12,605][root][ERROR] - Error
Traceback (most recent call last):
  File "/data/vision/torralba/frames/data_acquisition/SyntheticStories/agent_preferences/tshu/agent_preferences/analysis/helping_states.py", line 1477, in main
    res = manager.dict()
  File "/data/vision/torralba/frames/data_acquisition/SyntheticStories/agent_preferences/tshu/agent_preferences/analysis/helping_states.py", line 1477, in main
    res = manager.dict()
  File "/data/vision/torralba/frames/tools/anaconda3/envs/online_wah/lib/python3.9/bdb.py", line 88, in trace_dispatch
    return self.dispatch_line(frame)
  File "/data/vision/torralba/frames/tools/anaconda3/envs/online_wah/lib/python3.9/bdb.py", line 113, in dispatch_line
    if self.quitting: raise BdbQuit
bdb.BdbQuit
[2022-03-31 18:25:12,720][urllib3.connectionpool][WARNING] - Retrying (Retry(total=4, connect=4, read=5, redirect=None, status=None)) after connection broken by 'NewConnectionError('<urllib3.connection.HTTPConnection object at 0x7f617eafb760>: Failed to establish a new connection: [Errno 111] Connection refused')': /
[2022-03-31 18:26:12,944][urllib3.connectionpool][WARNING] - Retrying (Retry(total=4, connect=4, read=5, redirect=None, status=None)) after connection broken by 'NewConnectionError('<urllib3.connection.HTTPConnection object at 0x7ff67dd50730>: Failed to establish a new connection: [Errno 111] Connection refused')': /
[2022-03-31 18:26:16,947][urllib3.connectionpool][WARNING] - Retrying (Retry(total=3, connect=3, read=5, redirect=None, status=None)) after connection broken by 'NewConnectionError('<urllib3.connection.HTTPConnection object at 0x7ff67dd509d0>: Failed to establish a new connection: [Errno 111] Connection refused')': /
[2022-03-31 18:26:52,624][root][ERROR] - Error
Traceback (most recent call last):
  File "/data/vision/torralba/frames/data_acquisition/SyntheticStories/agent_preferences/tshu/agent_preferences/analysis/helping_states.py", line 1586, in main
    edge_steps[goal_edges[pred_id]],
KeyError: 'on_wineglass.402_coffeetable.247_init'
[2022-03-31 18:26:52,728][urllib3.connectionpool][WARNING] - Retrying (Retry(total=4, connect=4, read=5, redirect=None, status=None)) after connection broken by 'NewConnectionError('<urllib3.connection.HTTPConnection object at 0x7ff6c4157580>: Failed to establish a new connection: [Errno 111] Connection refused')': /
[2022-03-31 18:26:56,731][urllib3.connectionpool][WARNING] - Retrying (Retry(total=3, connect=3, read=5, redirect=None, status=None)) after connection broken by 'NewConnectionError('<urllib3.connection.HTTPConnection object at 0x7ff6c41577c0>: Failed to establish a new connection: [Errno 111] Connection refused')': /
[2022-03-31 18:31:05,864][urllib3.connectionpool][WARNING] - Retrying (Retry(total=4, connect=4, read=5, redirect=None, status=None)) after connection broken by 'NewConnectionError('<urllib3.connection.HTTPConnection object at 0x7f86ba5f9b50>: Failed to establish a new connection: [Errno 111] Connection refused')': /
[2022-03-31 18:31:09,867][urllib3.connectionpool][WARNING] - Retrying (Retry(total=3, connect=3, read=5, redirect=None, status=None)) after connection broken by 'NewConnectionError('<urllib3.connection.HTTPConnection object at 0x7f86ba5f9100>: Failed to establish a new connection: [Errno 111] Connection refused')': /
[2022-03-31 18:39:41,816][urllib3.connectionpool][WARNING] - Retrying (Retry(total=4, connect=4, read=5, redirect=None, status=None)) after connection broken by 'NewConnectionError('<urllib3.connection.HTTPConnection object at 0x7fc9b734eaf0>: Failed to establish a new connection: [Errno 111] Connection refused')': /
[2022-03-31 18:39:45,821][urllib3.connectionpool][WARNING] - Retrying (Retry(total=3, connect=3, read=5, redirect=None, status=None)) after connection broken by 'NewConnectionError('<urllib3.connection.HTTPConnection object at 0x7fc9b734e760>: Failed to establish a new connection: [Errno 111] Connection refused')': /
[2022-03-31 18:40:19,179][root][ERROR] - Error
Traceback (most recent call last):
  File "/data/vision/torralba/frames/data_acquisition/SyntheticStories/agent_preferences/tshu/agent_preferences/analysis/helping_states.py", line 1562, in main
    -args.beta * estimated_steps - args.lam * dist
TypeError: unsupported operand type(s) for *: 'float' and 'NoneType'
[2022-03-31 18:40:19,297][urllib3.connectionpool][WARNING] - Retrying (Retry(total=4, connect=4, read=5, redirect=None, status=None)) after connection broken by 'NewConnectionError('<urllib3.connection.HTTPConnection object at 0x7fc9f624e160>: Failed to establish a new connection: [Errno 111] Connection refused')': /
[2022-03-31 18:40:23,299][urllib3.connectionpool][WARNING] - Retrying (Retry(total=3, connect=3, read=5, redirect=None, status=None)) after connection broken by 'NewConnectionError('<urllib3.connection.HTTPConnection object at 0x7fc9f624e0d0>: Failed to establish a new connection: [Errno 111] Connection refused')': /
[2022-03-31 18:42:07,834][urllib3.connectionpool][WARNING] - Retrying (Retry(total=4, connect=4, read=5, redirect=None, status=None)) after connection broken by 'NewConnectionError('<urllib3.connection.HTTPConnection object at 0x7f563359da00>: Failed to establish a new connection: [Errno 111] Connection refused')': /
[2022-03-31 18:42:11,839][urllib3.connectionpool][WARNING] - Retrying (Retry(total=3, connect=3, read=5, redirect=None, status=None)) after connection broken by 'NewConnectionError('<urllib3.connection.HTTPConnection object at 0x7f56335cc1c0>: Failed to establish a new connection: [Errno 111] Connection refused')': /
[2022-03-31 18:42:45,716][root][ERROR] - Error
Traceback (most recent call last):
  File "/data/vision/torralba/frames/data_acquisition/SyntheticStories/agent_preferences/tshu/agent_preferences/analysis/helping_states.py", line 1563, in main
    -args.beta * estimated_steps - args.lam * dist
TypeError: unsupported operand type(s) for *: 'float' and 'NoneType'
[2022-03-31 18:42:45,793][urllib3.connectionpool][WARNING] - Retrying (Retry(total=4, connect=4, read=5, redirect=None, status=None)) after connection broken by 'NewConnectionError('<urllib3.connection.HTTPConnection object at 0x7f567dc6fdf0>: Failed to establish a new connection: [Errno 111] Connection refused')': /
[2022-03-31 18:43:48,656][urllib3.connectionpool][WARNING] - Retrying (Retry(total=4, connect=4, read=5, redirect=None, status=None)) after connection broken by 'NewConnectionError('<urllib3.connection.HTTPConnection object at 0x7f0b2853ea90>: Failed to establish a new connection: [Errno 111] Connection refused')': /
[2022-03-31 18:43:52,659][urllib3.connectionpool][WARNING] - Retrying (Retry(total=3, connect=3, read=5, redirect=None, status=None)) after connection broken by 'NewConnectionError('<urllib3.connection.HTTPConnection object at 0x7f0b285b56d0>: Failed to establish a new connection: [Errno 111] Connection refused')': /
[2022-03-31 18:44:24,726][root][ERROR] - Error
Traceback (most recent call last):
  File "/data/vision/torralba/frames/data_acquisition/SyntheticStories/agent_preferences/tshu/agent_preferences/analysis/helping_states.py", line 1538, in main
    if subgoal.endswith("init"):
AttributeError: 'NoneType' object has no attribute 'endswith'
[2022-03-31 18:44:24,819][urllib3.connectionpool][WARNING] - Retrying (Retry(total=4, connect=4, read=5, redirect=None, status=None)) after connection broken by 'NewConnectionError('<urllib3.connection.HTTPConnection object at 0x7f0b6743f3d0>: Failed to establish a new connection: [Errno 111] Connection refused')': /
[2022-03-31 18:44:28,823][urllib3.connectionpool][WARNING] - Retrying (Retry(total=3, connect=3, read=5, redirect=None, status=None)) after connection broken by 'NewConnectionError('<urllib3.connection.HTTPConnection object at 0x7f0b6743f1c0>: Failed to establish a new connection: [Errno 111] Connection refused')': /
[2022-03-31 18:48:04,075][urllib3.connectionpool][WARNING] - Retrying (Retry(total=4, connect=4, read=5, redirect=None, status=None)) after connection broken by 'NewConnectionError('<urllib3.connection.HTTPConnection object at 0x7feffaa57b50>: Failed to establish a new connection: [Errno 111] Connection refused')': /
[2022-03-31 18:48:08,079][urllib3.connectionpool][WARNING] - Retrying (Retry(total=3, connect=3, read=5, redirect=None, status=None)) after connection broken by 'NewConnectionError('<urllib3.connection.HTTPConnection object at 0x7feffaace250>: Failed to establish a new connection: [Errno 111] Connection refused')': /
[2022-03-31 18:48:40,222][root][ERROR] - Error
Traceback (most recent call last):
  File "/data/vision/torralba/frames/data_acquisition/SyntheticStories/agent_preferences/tshu/agent_preferences/analysis/helping_states.py", line 1597, in main
    edge_steps[goal_edges[pred_id]],
KeyError: 'on_waterglass.401_coffeetable.247_init'
[2022-03-31 18:48:40,320][urllib3.connectionpool][WARNING] - Retrying (Retry(total=4, connect=4, read=5, redirect=None, status=None)) after connection broken by 'NewConnectionError('<urllib3.connection.HTTPConnection object at 0x7ff049173a00>: Failed to establish a new connection: [Errno 111] Connection refused')': /
[2022-03-31 18:48:44,323][urllib3.connectionpool][WARNING] - Retrying (Retry(total=3, connect=3, read=5, redirect=None, status=None)) after connection broken by 'NewConnectionError('<urllib3.connection.HTTPConnection object at 0x7ff049173c40>: Failed to establish a new connection: [Errno 111] Connection refused')': /
[2022-03-31 18:49:06,269][root][ERROR] - Error
Traceback (most recent call last):
  File "/data/vision/torralba/frames/data_acquisition/SyntheticStories/agent_preferences/tshu/agent_preferences/analysis/helping_states.py", line 1597, in main
    edge_steps[goal_edges[pred_id]],
KeyError: 'on_pudding.405_coffeetable.247_init'
[2022-03-31 18:51:53,159][urllib3.connectionpool][WARNING] - Retrying (Retry(total=4, connect=4, read=5, redirect=None, status=None)) after connection broken by 'NewConnectionError('<urllib3.connection.HTTPConnection object at 0x7f63a310aa90>: Failed to establish a new connection: [Errno 111] Connection refused')': /
[2022-03-31 18:51:57,164][urllib3.connectionpool][WARNING] - Retrying (Retry(total=3, connect=3, read=5, redirect=None, status=None)) after connection broken by 'NewConnectionError('<urllib3.connection.HTTPConnection object at 0x7f63a3130f40>: Failed to establish a new connection: [Errno 111] Connection refused')': /
[2022-03-31 18:53:27,262][root][ERROR] - Error
Traceback (most recent call last):
  File "/data/vision/torralba/frames/data_acquisition/SyntheticStories/agent_preferences/tshu/agent_preferences/analysis/helping_states.py", line 1676, in main
    graph_result, steps - 3, change=True
  File "/data/vision/torralba/frames/data_acquisition/SyntheticStories/agent_preferences/tshu/agent_preferences/analysis/helping_states.py", line 1676, in main
    graph_result, steps - 3, change=True
  File "/data/vision/torralba/frames/tools/anaconda3/envs/online_wah/lib/python3.9/bdb.py", line 88, in trace_dispatch
    return self.dispatch_line(frame)
  File "/data/vision/torralba/frames/tools/anaconda3/envs/online_wah/lib/python3.9/bdb.py", line 113, in dispatch_line
    if self.quitting: raise BdbQuit
bdb.BdbQuit
[2022-03-31 18:53:27,391][urllib3.connectionpool][WARNING] - Retrying (Retry(total=4, connect=4, read=5, redirect=None, status=None)) after connection broken by 'NewConnectionError('<urllib3.connection.HTTPConnection object at 0x7f63cc3868e0>: Failed to establish a new connection: [Errno 111] Connection refused')': /
[2022-04-01 13:52:28,355][urllib3.connectionpool][WARNING] - Retrying (Retry(total=4, connect=4, read=5, redirect=None, status=None)) after connection broken by 'NewConnectionError('<urllib3.connection.HTTPConnection object at 0x7ff7273d12e0>: Failed to establish a new connection: [Errno 111] Connection refused')': /
[2022-04-01 13:52:32,360][urllib3.connectionpool][WARNING] - Retrying (Retry(total=3, connect=3, read=5, redirect=None, status=None)) after connection broken by 'NewConnectionError('<urllib3.connection.HTTPConnection object at 0x7ff7273e3e80>: Failed to establish a new connection: [Errno 111] Connection refused')': /
[2022-04-01 13:58:16,628][root][ERROR] - Error
Traceback (most recent call last):
  File "/data/vision/torralba/frames/data_acquisition/SyntheticStories/agent_preferences/tshu/agent_preferences/analysis/helping_states.py", line 1673, in main
    )
  File "/data/vision/torralba/frames/data_acquisition/SyntheticStories/agent_preferences/tshu/agent_preferences/analysis/helping_states.py", line 1673, in main
    )
  File "/data/vision/torralba/frames/tools/anaconda3/envs/online_wah/lib/python3.9/bdb.py", line 88, in trace_dispatch
    return self.dispatch_line(frame)
  File "/data/vision/torralba/frames/tools/anaconda3/envs/online_wah/lib/python3.9/bdb.py", line 113, in dispatch_line
    if self.quitting: raise BdbQuit
bdb.BdbQuit
[2022-04-01 13:58:16,790][urllib3.connectionpool][WARNING] - Retrying (Retry(total=4, connect=4, read=5, redirect=None, status=None)) after connection broken by 'NewConnectionError('<urllib3.connection.HTTPConnection object at 0x7ff74fe02790>: Failed to establish a new connection: [Errno 111] Connection refused')': /
[2022-04-01 13:58:31,623][urllib3.connectionpool][WARNING] - Retrying (Retry(total=4, connect=4, read=5, redirect=None, status=None)) after connection broken by 'NewConnectionError('<urllib3.connection.HTTPConnection object at 0x7f7c424ed790>: Failed to establish a new connection: [Errno 111] Connection refused')': /
[2022-04-01 13:58:35,628][urllib3.connectionpool][WARNING] - Retrying (Retry(total=3, connect=3, read=5, redirect=None, status=None)) after connection broken by 'NewConnectionError('<urllib3.connection.HTTPConnection object at 0x7f7c424e7d90>: Failed to establish a new connection: [Errno 111] Connection refused')': /
[2022-04-01 15:14:40,940][root][ERROR] - Error
Traceback (most recent call last):
  File "/data/vision/torralba/frames/data_acquisition/SyntheticStories/agent_preferences/tshu/agent_preferences/analysis/helping_states.py", line 1675, in main
    ipdb.set_trace()
  File "/data/vision/torralba/frames/data_acquisition/SyntheticStories/agent_preferences/tshu/agent_preferences/analysis/helping_states.py", line 1675, in main
    ipdb.set_trace()
  File "/data/vision/torralba/frames/tools/anaconda3/envs/online_wah/lib/python3.9/bdb.py", line 88, in trace_dispatch
    return self.dispatch_line(frame)
  File "/data/vision/torralba/frames/tools/anaconda3/envs/online_wah/lib/python3.9/bdb.py", line 113, in dispatch_line
    if self.quitting: raise BdbQuit
bdb.BdbQuit
[2022-04-01 15:14:41,092][urllib3.connectionpool][WARNING] - Retrying (Retry(total=4, connect=4, read=5, redirect=None, status=None)) after connection broken by 'NewConnectionError('<urllib3.connection.HTTPConnection object at 0x7f7c7913b820>: Failed to establish a new connection: [Errno 111] Connection refused')': /
[2022-04-01 15:14:55,000][urllib3.connectionpool][WARNING] - Retrying (Retry(total=4, connect=4, read=5, redirect=None, status=None)) after connection broken by 'NewConnectionError('<urllib3.connection.HTTPConnection object at 0x7f401a751ca0>: Failed to establish a new connection: [Errno 111] Connection refused')': /
[2022-04-01 15:14:59,003][urllib3.connectionpool][WARNING] - Retrying (Retry(total=3, connect=3, read=5, redirect=None, status=None)) after connection broken by 'NewConnectionError('<urllib3.connection.HTTPConnection object at 0x7f4019a50070>: Failed to establish a new connection: [Errno 111] Connection refused')': /
[2022-04-01 16:23:42,738][urllib3.connectionpool][WARNING] - Retrying (Retry(total=4, connect=4, read=5, redirect=None, status=None)) after connection broken by 'NewConnectionError('<urllib3.connection.HTTPConnection object at 0x7f56127d8d00>: Failed to establish a new connection: [Errno 111] Connection refused')': /
[2022-04-01 16:23:46,743][urllib3.connectionpool][WARNING] - Retrying (Retry(total=3, connect=3, read=5, redirect=None, status=None)) after connection broken by 'NewConnectionError('<urllib3.connection.HTTPConnection object at 0x7f56127d16a0>: Failed to establish a new connection: [Errno 111] Connection refused')': /
[2022-04-01 16:41:18,244][root][ERROR] - Error
Traceback (most recent call last):
  File "/data/vision/torralba/frames/data_acquisition/SyntheticStories/agent_preferences/tshu/agent_preferences/analysis/helping_states.py", line 1675, in main
    ipdb.set_trace()
  File "/data/vision/torralba/frames/data_acquisition/SyntheticStories/agent_preferences/tshu/agent_preferences/analysis/helping_states.py", line 1675, in main
    ipdb.set_trace()
  File "/data/vision/torralba/frames/tools/anaconda3/envs/online_wah/lib/python3.9/bdb.py", line 88, in trace_dispatch
    return self.dispatch_line(frame)
  File "/data/vision/torralba/frames/tools/anaconda3/envs/online_wah/lib/python3.9/bdb.py", line 113, in dispatch_line
    if self.quitting: raise BdbQuit
bdb.BdbQuit
[2022-04-01 16:41:18,399][urllib3.connectionpool][WARNING] - Retrying (Retry(total=4, connect=4, read=5, redirect=None, status=None)) after connection broken by 'NewConnectionError('<urllib3.connection.HTTPConnection object at 0x7f564be16640>: Failed to establish a new connection: [Errno 111] Connection refused')': /
[2022-04-01 16:41:22,404][urllib3.connectionpool][WARNING] - Retrying (Retry(total=3, connect=3, read=5, redirect=None, status=None)) after connection broken by 'NewConnectionError('<urllib3.connection.HTTPConnection object at 0x7f564be16a30>: Failed to establish a new connection: [Errno 111] Connection refused')': /
[2022-04-01 16:42:52,457][urllib3.connectionpool][WARNING] - Retrying (Retry(total=4, connect=4, read=5, redirect=None, status=None)) after connection broken by 'NewConnectionError('<urllib3.connection.HTTPConnection object at 0x7f8512ff7640>: Failed to establish a new connection: [Errno 111] Connection refused')': /
[2022-04-01 16:42:56,459][urllib3.connectionpool][WARNING] - Retrying (Retry(total=3, connect=3, read=5, redirect=None, status=None)) after connection broken by 'NewConnectionError('<urllib3.connection.HTTPConnection object at 0x7f8512ff4460>: Failed to establish a new connection: [Errno 111] Connection refused')': /
[2022-04-01 16:43:46,176][root][ERROR] - Error
Traceback (most recent call last):
  File "/data/vision/torralba/frames/data_acquisition/SyntheticStories/agent_preferences/tshu/agent_preferences/analysis/helping_states.py", line 1677, in main
    edge_pred_class_estimated = aggregate_multiple_pred(
  File "/data/vision/torralba/frames/data_acquisition/SyntheticStories/agent_preferences/tshu/agent_preferences/analysis/helping_states.py", line 1677, in main
    edge_pred_class_estimated = aggregate_multiple_pred(
  File "/data/vision/torralba/frames/tools/anaconda3/envs/online_wah/lib/python3.9/bdb.py", line 88, in trace_dispatch
    return self.dispatch_line(frame)
  File "/data/vision/torralba/frames/tools/anaconda3/envs/online_wah/lib/python3.9/bdb.py", line 113, in dispatch_line
    if self.quitting: raise BdbQuit
bdb.BdbQuit
[2022-04-01 16:43:46,403][urllib3.connectionpool][WARNING] - Retrying (Retry(total=4, connect=4, read=5, redirect=None, status=None)) after connection broken by 'NewConnectionError('<urllib3.connection.HTTPConnection object at 0x7f84e6a61370>: Failed to establish a new connection: [Errno 111] Connection refused')': /
[2022-04-01 16:44:03,933][urllib3.connectionpool][WARNING] - Retrying (Retry(total=4, connect=4, read=5, redirect=None, status=None)) after connection broken by 'NewConnectionError('<urllib3.connection.HTTPConnection object at 0x7f9c12f47c10>: Failed to establish a new connection: [Errno 111] Connection refused')': /
[2022-04-01 16:44:07,938][urllib3.connectionpool][WARNING] - Retrying (Retry(total=3, connect=3, read=5, redirect=None, status=None)) after connection broken by 'NewConnectionError('<urllib3.connection.HTTPConnection object at 0x7f9c12f47400>: Failed to establish a new connection: [Errno 111] Connection refused')': /
